Workbook

Sheet Sheet1
A1: V.1.0.2 | C1: 경영진 체크, 지분율, 주식수(보통주, 자기주식 등 정리), 배당, 연결 개별 실제지분정도 (제표상 확인사항 등), 산업전망, 매크로연관성 등, PEER대비 밴드및 상대ROE등, ROE+부채율 ROA등확인 | T1: Y0 | U1: Y+1 | V1: Y+2
C2: =C147 -> 오파스넷 | D2: =D157 -> 16년 | E2: =E157 -> 17년 | F2: =F157 -> 18년 | G2: =G157 -> 19년 | H2: =H157 -> 20년 | I2: =I157 -> 21년 | J2: =J157 -> 22년 | K2: =K157 -> 23년 | ... M2: =M157 -> 25년3Q연환산 | N2: =O157 -> 0 | P2: =P157 -> 분기 손익계산서 | Q2: =#REF! -> #REF! | R2: =Q157 -> 24.3Q | S2: =R157 -> 24.4Q | T2: =S157 -> 25.1Q | U2: =T157 -> 25.2Q | V2: =U157 -> 25.3Q
C3: =[1]Src!BP5 -> 시스템서비스 | D3: Y-8 | E3: Y-7 | F3: Y-6 | G3: Y-5 | H3: Y-4 | I3: Y-3 | J3: Y-2 | K3: Y-1 | Q3: Q-5 | R3: Q-4 | S3: Q-3 | T3: Q-2 | U3: Q-1 | V3: Q(E)
C4: ROE | D4: =D211 -> 0 | E4: =E211 -> 10.6 | F4: =F211 -> 7.57 | G4: =G211 -> -67.18 | H4: =H211 -> 26.63 | I4: =I211 -> 21.59 | J4: =J211 -> 17.18 | K4: =K211 -> 22.73 | ... M4: =M211 -> 23.93 | N4: =O211 -> 0 | P4: =C4 -> ROE | S4: =[1]ROE!W371 -> 0 | T4: =[1]ROE!X371 -> 0 | U4: =L211/4 -> 4.43 | V4: =M211/4 -> 5.9825
C5: 지배 자기자본 | D5: =D275 -> 132 | E5: =E275 -> 166 | F5: =F275 -> 302 | G5: =G275 -> 177 | H5: =H275 -> 226 | I5: =I275 -> 291 | J5: =J275 -> 353 | K5: =K275 -> 460 | ... M5: =M275 -> 606 | N5: =O275 -> 0 | P5: =C5 -> 지배 자기자본 | U5: =L275 -> 539 | V5: =M275 -> 606
C6: EPS | D6: =D179 -> 0 | E6: =E179 -> 184 | F6: =F179 -> 176 | G6: =G179 -> -911 | H6: =H179 -> 1359 | I6: =I179 -> 481 | J6: =J179 -> 465 | K6: =K179 -> 881 | ... M6: =M179 -> 1111.11 | N6: =O179 -> 620.69 | P6: =C6 -> EPS | Q6: =#REF! -> #REF! | R6: =Q171 -> 130.27 | S6: =R171 -> 490.42 | T6: =S171 -> 38.31 | U6: =T171 -> 352.49 | V6: =U171 -> 229.89
C7: DPS | D7: =D182 -> 0 | E7: =E182 -> 0 | F7: =F182 -> 0 | G7: =G182 -> 0 | H7: =H182 -> 0 | I7: =I182 -> 45 | J7: =J182 -> 45 | K7: =K182 -> 136 | ... M7: =M182 -> 100 | N7: =O182 -> 0
C8: 배당율 | D8: =D215 -> 0 | E8: =E215 -> 0 | F8: =F215 -> 0 | G8: =G215 -> 0 | H8: =H215 -> 0 | I8: =I215 -> 1.25 | J8: =J215 -> 0.58 | K8: =K215 -> 1.16 | ... M8: =M215 -> 1.59 | N8: =O215 -> 1.36
C9: 시가총액 | D9: =[1]Src!BQ31 -> 115 | E9: =[1]Src!BR31 -> 120 | F9: =[1]Src!BS31 -> 509 | G9: =[1]Src!BT31 -> 259 | H9: =[1]Src!BU31 -> 242 | I9: =[1]Src!BV31 -> 470 | J9: =[1]Src!BW31 -> 1009 | K9: =[1]Src!BX31 -> 1390 | ... N9: =[1]Src!CA31 -> 963
C10: 주가 | D10: =[1]Src!BQ32 -> 1271 | E10: =[1]Src!BR32 -> 1251 | F10: =[1]Src!BS32 -> 3907 | G10: =[1]Src!BT32 -> 1986 | H10: =[1]Src!BU32 -> 5463 | I10: =[1]Src!BV32 -> 3604 | J10: =[1]Src!BW32 -> 7736 | K10: =[1]Src!BX32 -> 11720 | ... N10: =[1]Src!CA32 -> 7380
C11: *ROE계산 | E11: =[1]Src!BQ16/AVERAGE([1]Src!BQ131) -> 0.15909091 | F11: =[1]Src!BR16/AVERAGE([1]Src!BQ131:BR131) -> 0.20805369 | G11: =[1]Src!BS16/AVERAGE([1]Src!BR131:BS131) -> 0.098290598 | H11: =[1]Src!BT16/AVERAGE([1]Src!BS131:BT131) -> -0.49686848 | I11: =[1]Src!BU16/AVERAGE([1]Src!BT131:BU131) -> 0.29776675 | J11: =[1]Src!BV16/AVERAGE([1]Src!BU131:BV131) -> 0.23984526 | K11: =[1]Src!BW16/AVERAGE([1]Src!BV131:BW131) -> 0.18944099 | L11: =[1]Src!BX16/AVERAGE([1]Src!BW131:BX131) -> 0.25830258 | M11: =[1]Src!BY16/AVERAGE([1]Src!BX131:BY131) -> 0.19019019 | N11: =[1]Src!BZ16/AVERAGE(H13,K5) -> 0.26696394
C12: ROE 추정 | D12: 지속기간 | E12: 가중평균 | F12: 분기포함평균 | G12: 9년 평균 | H12: (B)자기자본 추정 | I12: 추정값 | J12: 보정CAGR(5y) | K12: 보정율 | L12: CAGR(5y) | M12: CAGR 임의 | N12: PBR CAGR (A) | O12: 24 자기자본
C13: 10 | D13: 7 | E13: =(K4*3+J4*2+I4)/6 -> 20.69 | F13: =AVERAGE(J4:L4) -> 19.21 | G13: =AVERAGE(F4:L4) -> 6.6057143 | H13: =L5*(1+J15) -> 626.28903 | I13: =L5*(1+J13) -> 653.29108 | J13: =K13*L13 -> 0.21204282 | K13: 0.85 | L13: =(L5/G5)^(1/(COLUMN(L5)-COLUMN(G5)))-1 -> 0.24946214 | M13: =(L5/I5)^(1/(COUNTA(I5:L5)-1))-1 -> 0.22809489 | N13: =[1]PB!Y4 -> #VALUE! | O13: =[1]Src!CP4*[1]PB!AF14 -> 539
C14: =AVERAGE(M11,I11:L11) -> 0.23510916 | D14: 5yr avg | H14: 1 | I14: 2 | J14: 3 | K14: 4 | L14: 5 | M14: 6 | N14: 7 | O14: 8 | P14: 9 | Q14: 10
C15: 1 | D15: 2 | E15: =D15+1 -> 3 | F15: =E15+1 -> 4 | G15: =F15+1 -> 5 | H15: ver.B | J15: =[1]PB!AA6 -> 0.16194626 | K15: *PB CAGR 참고치 | M15: ver.A | N15: EPS 보정률 : | O15: =[1]PE!AA6 -> #VALUE! | P15: 0.95 | Q15: 0.95
C16: FnGuide | D16: =VLOOKUP($C16,$H$16:$Q$19,($C$15-1)*5+D$15,0) -> 23년 | E16: =VLOOKUP($C16,$H$16:$Q$19,($C$15-1)*5+E$15,0) -> 24년 | F16: =VLOOKUP($C16,$H$16:$Q$19,($C$15-1)*5+F$15,0) -> 25E | G16: =VLOOKUP($C16,$H$16:$Q$19,($C$15-1)*5+G$15,0) -> 26E | H16: FnGuide | I16: =[1]Src!CO2 -> 23년 | J16: =[1]Src!CP2 -> 24년 | K16: =[1]Src!CQ2 -> 25E | L16: =[1]Src!CR2 -> 26E | M16: FnGuide | N16: =[1]Src!CO2 -> 23년 | O16: =[1]Src!CP2 -> 24년 | P16: =[1]Src!CQ2 -> 25E | Q16: =[1]Src!CR2 -> 26E
C17: 지배순익 | D17: =VLOOKUP($C17,$H$16:$Q$19,($C$15-1)*5+D$15,0) -> 105 | E17: =VLOOKUP($C17,$H$16:$Q$19,($C$15-1)*5+E$15,0) -> 95 | F17: =VLOOKUP($C17,$H$16:$Q$19,($C$15-1)*5+F$15,0) -> #VALUE! | G17: =VLOOKUP($C17,$H$16:$Q$19,($C$15-1)*5+G$15,0) -> #VALUE! | H17: 지배순익 | I17: =[1]Src!CO3 -> 105 | J17: =[1]Src!CP3 -> 95 | K17: =J17*(1+$J$22) -> #VALUE! | L17: =K17*(1+$K$22) -> #VALUE! | M17: 지배순익 | N17: =[1]Src!CO3 -> 105 | O17: =[1]Src!CP3 -> 95 | P17: =[1]Src!CQ3*P15 -> #VALUE! | Q17: =[1]Src!CR3*Q15 -> #VALUE!
C18: 자기자본 | D18: =VLOOKUP($C18,$H$16:$Q$19,($C$15-1)*5+D$15,0) -> 460 | E18: =VLOOKUP($C18,$H$16:$Q$19,($C$15-1)*5+E$15,0) -> 539 | F18: =VLOOKUP($C18,$H$16:$Q$19,($C$15-1)*5+F$15,0) -> 643.74684 | G18: =VLOOKUP($C18,$H$16:$Q$19,($C$15-1)*5+G$15,0) -> 768.84971 | H18: 자기자본 | I18: =[1]Src!CO4 -> 460 | J18: =[1]Src!CP4 -> 539 | K18: =J18*(1+$J$15*K23) -> 643.74684 | L18: =K18*(1+$J$15*K23) -> 768.84971 | M18: 자기자본 | N18: =[1]Src!CO4 -> 460 | O18: =[1]Src!CP4 -> 539 | P18: =[1]Src!CQ4*[1]PB!AF10 -> #VALUE! | Q18: =P18*([1]PB!V2+1*0.9) -> #VALUE! | R18: *BPS 보정 | S18: =[1]Src!CR4*[1]PB!AF10 -> #VALUE!
C19: ROE | D19: =VLOOKUP($C19,$H$16:$Q$19,($C$15-1)*5+D$15,0) -> 25.830258 | E19: =VLOOKUP($C19,$H$16:$Q$19,($C$15-1)*5+E$15,0) -> 19.019019 | F19: =VLOOKUP($C19,$H$16:$Q$19,($C$15-1)*5+F$15,0) -> #VALUE! | G19: =VLOOKUP($C19,$H$16:$Q$19,($C$15-1)*5+G$15,0) -> #VALUE! | H19: ROE | I19: =I17/AVERAGE(J5,I18)*100 -> 25.830258 | J19: =J17/AVERAGE(I18,J18)*100 -> 19.019019 | K19: =K17/AVERAGE(J18,K18)*100 -> #VALUE! | L19: =L17/AVERAGE(K18,L18)*100 -> #VALUE! | M19: ROE | N19: =N17/AVERAGE(J5,N18)*100 -> 25.830258 | O19: =O17/AVERAGE(N18,O18)*100 -> 19.019019 | P19: =P17/AVERAGE(O18,P18)*100 -> #VALUE! | Q19: =Q17/AVERAGE(P18,Q18)*100 -> #VALUE! | S19: 26년 자기자본백업
J20: =[1]PE!$AB$7 -> 0 | K20: *(B) PE CAGR 기본 (변동성큰경우) | M20: *자기자본도 순익과 함께 감해야하지만, 보수적 ROE 위해 예상치 유지
J21: =[1]PE!$Z$7 -> #VALUE! | K21: *PE CAGR 조정값 | O21: =O18/N18-1 -> 0.17173913 | P21: =P18/O18-1 -> #VALUE! | Q21: =Q18/P18-1 -> #VALUE!
G22: EPS | H22: 선택값 → | I22: =[1]PE!Z6 -> #VALUE! | J22: =[1]PE!Z7 -> #VALUE! | K22: =[1]PE!Z8 -> #VALUE!
G23: BPS | K23: =[1]PB!AA11 -> 1.2 | N23: 항목 | O23: 보통주 | P23: 지분율 | Q23: 최종변동일
D24: =G30 -> #VALUE! | E24: =E31 -> -0.13286362 | K24: *미래 ROE는 동일한 값으로 가정해야할듯- 기업가치 정의 상 | N24: =[1]Src!CW4 -> 장수현(외 7인) | O24: =[1]Src!CX4 -> 5387915 | P24: =[1]Src!CY4 -> 41.3 | Q24: =[1]Src!CZ4 -> 46014 | T24: TOP | U24: 수익률 | W24: BOT | X24: 방어율
D25: =T26 -> #VALUE! | E25: =T26/D30-1 -> #VALUE! | F25: =W26 -> #VALUE! | G25: =X26 -> #VALUE! | I25: *Y-1 당시 기준 추정값 대비 실제 주가 비교 점검항목 추가? | L25: 주식수원본 → | M25: =L225-$N$31 -> 1304.6611 | N25: =[1]Src!CW5 -> 자사주 | O25: =[1]Src!CX5 -> 3389 | P25: =[1]Src!CY5 -> 0.03 | Q25: =[1]Src!CZ5 -> 45401 | R25: 27년 | S25: 2 | T25: =G28*S25 -> 18805.24 | U25: =T25/D28-1 -> 1.6301035 | V25: 1.5 | W25: =V25*F28 -> 0 | X25: =W25/D27-1 -> #VALUE!
C26: ○ S-RIM | E26: w | F26: 0.8 | G26: 0.9 | H26: 1 | I26: CAGR | J26: =(I31/I35)^(1/5)-1 -> 0.21047803 | K26: 보정율 | L26: 0.85 | M26: 0.85 | N26: =IFERROR(VLOOKUP("자사주",[1]Src!$CW$3:$CZ$30,1,0),"") -> 자사주 | O26: =IFERROR(VLOOKUP("자사주",[1]Src!$CW$3:$CZ$30,2,0),"") -> 3389 | P26: =IFERROR(VLOOKUP("자사주",[1]Src!$CW$3:$CZ$30,3,0),"") -> 0.03 | Q26: =IFERROR(VLOOKUP("자사주",[1]Src!$CW$3:$CZ$30,4,0),"") -> 45401 | R26: 26년 | S26: 1.7 | T26: =AVERAGE(G29)*S26 -> #VALUE! | U26: =T26/D29-1 -> #VALUE! | V26: 1.15 | W26: =AVERAGE(F29)*V26 -> #VALUE! | X26: =W26/D28-1 -> #VALUE!
C27: 예상연도 | D27: 종가(현재가) | E27: 갭수익률 | F27: 기준 매수가 | G27: 1차 매도가 | H27: 2차 매도가 | I27: 지배자기자본(기초) | J27: ROE | K27: 장기ROE | L27: 요구수익률 | M27: 지배주식수(만) | N27: 자사주 수(만) | O27: 우선주 수(만) | P27: 주당 자기자본 | Q27: 멀티플(1차대비) | R27: 최고가 | S27: TP달성율 | T27: 최저가 | U27: 매수가대비 | V27: 440 | X27: 기업가치=자산+초과이익PV | AB27: S-RIM 식 검증
B28: 27 | C28: Y+2 | D28: =IFERROR(__xludf.DUMMYFUNCTION("IFERROR(GoogleFinance(""kosdaq:""&RIGHT($D$147,6),""price""),GoogleFinance(""krx:""&RIGHT($D$147,6),""price""))"),7150) -> 7150 | G28: =(($I28+($I28*($K28-$L28))*(G$26/(1+$L28-G$26)))/$M28)*10000 -> 9402.6201 | I28: =G18 -> 768.84971 | J28: 0.2 | K28: =J28 -> 0.2 | L28: =L29 -> 0.1 | M28: =M29 -> 1185.6611 | R28: 현재가기준 → | T28: 현재가기준 →
B29: 26 | C29: Y+2 | D29: =IFERROR(__xludf.DUMMYFUNCTION("IFERROR(GoogleFinance(""kosdaq:""&RIGHT($D$147,6),""price""),GoogleFinance(""krx:""&RIGHT($D$147,6),""price""))"),7150) -> 7150 | E29: =G29/D29-1 -> #VALUE! | F29: =(($I29+($I29*($K29-$L29))*(F$26/(1+$L29-F$26)))/$M29)*10000 -> #VALUE! | G29: =(($I29+($I29*($K29-$L29))*(G$26/(1+$L29-G$26)))/$M29)*10000 -> #VALUE! | H29: =(($I29+($I29*($K29-$L29))*(H$26/(1+$L29-H$26)))/$M29)*10000 -> #VALUE! | I29: =F18 -> 643.74684 | J29: =G19/100 -> #VALUE! | K29: =J29 -> #VALUE! | L29: 0.1 | M29: =M31-N29 -> 1185.6611 | R29: =[1]배당!R2 -> 7930 | T29: =[1]배당!S2 -> 6100 | X29: =지배지분+[지배지분*(ROE-r)/r] | AB29: 적정매수 | AC29: 1차 매도가 | AD29: 2차 매도가
B30: 25 | C30: Y1 | D30: =[1]PE!G13 -> 6640 | E30: =G30/D30-1 -> #VALUE! | F30: =(($I30+($I30*($K30-$L30))*(F$26/(1+$L30-F$26)))/$M30)*10000 -> #VALUE! | G30: =(($I30+($I30*($K30-$L30))*(G$26/(1+$L30-G$26)))/$M30)*10000 -> #VALUE! | H30: =(($I30+($I30*($K30-$L30))*(H$26/(1+$L30-H$26)))/$M30)*10000 -> #VALUE! | I30: =E18 -> 539 | J30: =F19/100 -> #VALUE! | K30: =J30 -> #VALUE! | L30: 0.1 | M30: =M31 -> 1185.6611 | N30: =O25/10000 -> 0.3389 | P30: =I30/M30*10000 -> 4545.987 | Q30: =D30/F30-1 -> #VALUE! | R30: =[1]배당!R3 -> 11430 | S30: =D30/G30 -> #VALUE! | T30: =[1]배당!S3 -> 5580 | U30: =D30/F30 -> #VALUE! | V30: 25 | X30: =>지배지분+ 지배지분*(ROE-r)*w/(1+r-w) | Z30: =$I31*($J32-$L31)*G$26 -> 65.537269 | AA30: =$I31*($J32-$L31)*H$26 -> 72.819188 | AB30: =($I31+Y$33)/$M31*10000 -> 5517.4662 | AC30: =($I31+Z$32)/$M31*10000 -> 6643.4359 | AD30: =($I31+AA$32)/$M31*10000 -> 10021.345
B31: 24 | C31: Y0 | D31: =[1]PE!G14 -> 6290 | E31: =G31/D31-1 -> -0.13286362 | F31: =(($I31+($I31*($K31-$L31))*(F$26/(1+$L31-F$26)))/$M31)*10000 -> 4812.7859 | G31: =(($I31+($I31*($K31-$L31))*(G$26/(1+$L31-G$26)))/$M31)*10000 -> 5454.2879 | H31: =(($I31+($I31*($K31-$L31))*(H$26/(1+$L31-H$26)))/$M31)*10000 -> 7378.7938 | I31: =D18 -> 460 | J31: =E19/100 -> 0.19019019 | K31: =J31 -> 0.19019019 | L31: 0.1 | M31: =M32 -> 1185.6611 | N31: =N30 -> 0.3389 | P31: =I31/M31*10000 -> 3879.6921 | Q31: =D31/F31-1 -> 0.30693535 | R31: =[1]배당!R4 -> 12220 | S31: =R31/G31 -> 2.2404391 | T31: =[1]배당!S4 -> 5770 | U31: =T31/F31 -> 1.1988898 | V31: 24 | X31: 초과이익*w | Y31: =$I31*($J32-$L31)*F$26 -> 58.255351 | Z31: =1+$L31-G$26 -> 0.2 | AA31: =1+$L31-H$26 -> 0.1
B32: 23 | C32: Y-1 | D32: =K10 -> 11720 | E32: =G32/D32-1 -> -0.56500726 | F32: =(($I32+($I32*($K32-$L32))*(F$26/(1+$L32-F$26)))/$M32)*10000 -> 4234.0556 | G32: =(($I32+($I32*($K32-$L32))*(G$26/(1+$L32-G$26)))/$M32)*10000 -> 5098.1149 | H32: =(($I32+($I32*($K32-$L32))*(H$26/(1+$L32-H$26)))/$M32)*10000 -> 7690.2929 | I32: =J5 -> 353 | J32: =D19/100 -> 0.25830258 | K32: =J32 -> 0.25830258 | L32: 0.1 | M32: =K225-N32 -> 1185.6611 | N32: =N31 -> 0.3389 | P32: =I32/M32*10000 -> 2977.242 | Q32: =D32/F32-1 -> 1.7680317 | R32: =[1]배당!R5 -> 18135 | S32: =R32/G32 -> 3.5571972 | T32: =[1]배당!S5 -> 7045 | U32: =T32/F32 -> 1.6638894 | V32: 23 | X32: 1+할인율-w | Y32: =1+$L31-F$26 -> 0.3 | Z32: =Z30/Z31 -> 327.68635 | AA32: =AA30/AA31 -> 728.19188
B33: 22 | C33: =J3 -> Y-2 | D33: =J10 -> 7736 | E33: =G33/D33-1 -> -0.61852025 | F33: =(($I33+($I33*($K33-$L33))*(F$26/(1+$L33-F$26)))/$M33)*10000 -> 2657.5239 | G33: =(($I33+($I33*($K33-$L33))*(G$26/(1+$L33-G$26)))/$M33)*10000 -> 2951.1273 | H33: =(($I33+($I33*($K33-$L33))*(H$26/(1+$L33-H$26)))/$M33)*10000 -> 3831.9377 | I33: =I5 -> 291 | J33: =J4/100 -> 0.1718 | K33: =J33 -> 0.1718 | L33: 0.1 | M33: =J225-N33 -> 1304.6611 | N33: =N32 -> 0.3389 | P33: =I33/M33*10000 -> 2230.4643 | Q33: =D33/F33-1 -> 1.9109805 | R33: =[1]배당!R6 -> 11090 | S33: =R33/G33 -> 3.757886 | T33: =[1]배당!S6 -> 3009 | U33: =T33/F33 -> 1.132257 | V33: 22 | X33: 이익분 | Y33: =Y31/Y32 -> 194.1845
B34: 21 | C34: =I3 -> Y-3 | D34: =I10 -> 3604 | E34: =G34/D34-1 -> -0.26867205 | F34: =(($I34+($I34*($K34-$L34))*(F$26/(1+$L34-F$26)))/$M34)*10000 -> 2267.6315 | G34: =(($I34+($I34*($K34-$L34))*(G$26/(1+$L34-G$26)))/$M34)*10000 -> 2635.7059 | H34: =(($I34+($I34*($K34-$L34))*(H$26/(1+$L34-H$26)))/$M34)*10000 -> 3739.9291 | I34: =H5 -> 226 | J34: =I4/100 -> 0.2159 | K34: =J34 -> 0.2159 | L34: 0.1 | M34: =I225-N34 -> 1304.6611 | N34: =N33 -> 0.3389 | P34: =I34/M34*10000 -> 1732.2506 | Q34: =D34/F34-1 -> 0.58932345 | R34: =[1]배당!R7 -> 5463 | S34: =R34/G34 -> 2.0726895 | T34: =[1]배당!S7 -> 3331 | U34: =T34/F34 -> 1.4689335 | V34: 21
B35: 20 | C35: =H3 -> Y-4 | D35: =H10 -> 5463 | E35: =G35/D35-1 -> 0.27967323 | F35: =(($I35+($I35*($K35-$L35))*(F$26/(1+$L35-F$26)))/$M35)*10000 -> 5771.7654 | G35: =(($I35+($I35*($K35-$L35))*(G$26/(1+$L35-G$26)))/$M35)*10000 -> 6990.8549 | H35: =(($I35+($I35*($K35-$L35))*(H$26/(1+$L35-H$26)))/$M35)*10000 -> 10648.123 | I35: =G5 -> 177 | J35: =H4/100 -> 0.2663 | K35: =J35 -> 0.2663 | L35: 0.1 | M35: =H225-N35 -> 442.6611 | N35: =N34 -> 0.3389 | P35: =I35/M35*10000 -> 3998.5443 | Q35: =D35/F35-1 -> -0.053495826 | R35: =[1]배당!R8 -> 6181 | S35: =R35/G35 -> 0.8841551 | T35: =[1]배당!S8 -> 1513 | U35: =T35/F35 -> 0.26213817 | V35: 20
B36: 19 | C36: =G3 -> Y-5 | D36: =G10 -> 1986 | E36: =G36/D36-1 -> -3.8869412 | F36: =(($I36+($I36*($K36-$L36))*(F$26/(1+$L36-F$26)))/$M36)*10000 -> -2453.1036 | G36: =(($I36+($I36*($K36-$L36))*(G$26/(1+$L36-G$26)))/$M36)*10000 -> -5733.4651 | H36: =(($I36+($I36*($K36-$L36))*(H$26/(1+$L36-H$26)))/$M36)*10000 -> -15574.55 | I36: =F5 -> 302 | J36: =G4/100 -> -0.6718 | K36: =J36 -> -0.6718 | L36: 0.1 | M36: =G$225-N36 -> 1302.6611 | N36: =N35 -> 0.3389 | P36: =I36/M36*10000 -> 2318.3313 | Q36: =D36/F36-1 -> -1.8095867 | R36: =[1]배당!R9 -> 4942 | S36: =R36/G36 -> -0.86195693 | T36: =[1]배당!S9 -> 1690 | U36: =T36/F36 -> -0.6889232 | V36: 19
B37: 18 | C37: =F3 -> Y-6 | D37: =F10 -> 3907 | E37: =G37/D37-1 -> -0.7095039 | F37: =(($I37+($I37*($K37-$L37))*(F$26/(1+$L37-F$26)))/$M37)*10000 -> 1191.739 | G37: =(($I37+($I37*($K37-$L37))*(G$26/(1+$L37-G$26)))/$M37)*10000 -> 1134.9683 | H37: =(($I37+($I37*($K37-$L37))*(H$26/(1+$L37-H$26)))/$M37)*10000 -> 964.65612 | I37: =E5 -> 166 | J37: =F4/100 -> 0.0757 | K37: =J37 -> 0.0757 | L37: 0.1 | M37: =F$225-N37 -> 1302.6611 | N37: =N36 -> 0.3389 | P37: =I37/M37*10000 -> 1274.3146 | Q37: =D37/F37-1 -> 2.2784025 | R37: =[1]배당!R10 -> 6054 | S37: =R37/G37 -> 5.3340699 | T37: =[1]배당!S10 -> 1251 | U37: =T37/F37 -> 1.0497265 | V37: 18 | X37: *각 연말 추정치 vs 각연도 최고가, 촤저가, 종가 비교
B38: 17 | C38: =E3 -> Y-7 | D38: =E10 -> 1251 | E38: =G38/D38-1 -> 0.12802016 | F38: =(($I38+($I38*($K38-$L38))*(F$26/(1+$L38-F$26)))/$M38)*10000 -> 1396.0386 | G38: =(($I38+($I38*($K38-$L38))*(G$26/(1+$L38-G$26)))/$M38)*10000 -> 1411.1532 | H38: =(($I38+($I38*($K38-$L38))*(H$26/(1+$L38-H$26)))/$M38)*10000 -> 1456.497 | I38: =D5 -> 132 | J38: =E4/100 -> 0.106 | K38: =J38 -> 0.106 | L38: 0.1 | M38: =E$225-N38 -> 960.6611 | N38: =N37 -> 0.3389 | P38: =I38/M38*10000 -> 1374.0538 | Q38: =D38/F38-1 -> -0.10389299 | R38: =[1]배당!R11 -> 1271 | S38: =R38/G38 -> 0.90068179 | T38: =[1]배당!S11 -> 1233 | U38: =T38/F38 -> 0.88321339 | V38: 17
B39: 16 | C39: =D3 -> Y-8 | D39: =D10 -> 1271 | E39: =G39/D39-1 -> #REF! | F39: =(($I39+($I39*($K39-$L39))*(F$26/(1+$L39-F$26)))/$M39)*10000 -> #REF! | G39: =(($I39+($I39*($K39-$L39))*(G$26/(1+$L39-G$26)))/$M39)*10000 -> #REF! | H39: =(($I39+($I39*($K39-$L39))*(H$26/(1+$L39-H$26)))/$M39)*10000 -> #REF! | I39: =#REF! -> #REF! | J39: =D4/100 -> 0 | K39: =J39 -> 0 | L39: 0.1 | M39: =D$225-N39 -> 902.6611 | N39: =N38 -> 0.3389 | P39: =I39/M39*10000 -> #REF! | Q39: =D39/F39-1 -> #REF! | R39: =[1]배당!R12 -> 1271 | S39: =R39/G39 -> #REF! | T39: =[1]배당!S12 -> 1271 | U39: =T39/F39 -> #REF! | V39: 16
H40: *ROE가 0이하이면 기업가치가 없음? → 정의상 ROE가 장기지속 ROE값이기 때문에 오차발생 : 수식 보정이 필요/ 과거 시점별 밸류에이션 무의미함 | T40: =[1]배당!S13 -> 0
...

Sheet Sheet2
A1: v1.5 | C1: =[1]ROE!C2 -> 오파스넷 | D1: 현재가 | E1: SCORE | F1: 現배당율 | G1: 매수목표 | H1: SCORE | I1: T배당율 | J1: 46071 | K1: SCORE | L1: EPS'24 | N1: SCORE | Q1: FnGuide EPS | R1: 23 | S1: 24 | T1: 25 | U1: 26 | V1: =Y8 -> #VALUE! | W1: 24 Fn | X1: 1Q | Y1: 2Q | Z1: 3Q | AA1: 4Q | AB1: 1 | AC1: 4 | AD1: =AC1+1 -> 5 | AE1: =AD1+1 -> 6 | AF1: =AE1+1 -> 7 | AG1: 3Q | AH1: 4Q | AJ1: 증가율 | AK1: =[1]①DATA!E18 -> 18년 | AL1: =[1]①DATA!F18 -> 19년 | AM1: =[1]①DATA!G18 -> 20년 | AN1: =[1]①DATA!H18 -> 21년 | AO1: =[1]①DATA!I18 -> 22년 | AP1: =[1]①DATA!J18 -> 23년 | AQ1: =[1]①DATA!K18 -> 24년 | AR1: =[1]①DATA!L18 -> 25년3Q연환산
D2: =IFERROR(__xludf.DUMMYFUNCTION("iferror(GoogleFinance(""kosdaq:""&C3, ""price""),GoogleFinance(""krx:""&C3, ""price""))"),7150) -> 7150 | E2: =E4+H4 -> #VALUE! | F2: =[1]배당!$T$2/D2 -> 0.016783217 | G2: =G4*1.1 -> #VALUE! | H2: =D4/G2-1+G4/G2-1 -> #VALUE! | I2: =[1]배당!$T$2/G2 -> #VALUE! | J2: =IFERROR(__xludf.DUMMYFUNCTION("iferror(index((GoogleFinance(""kosdaq:""&$C$3, ""price"", $J$1-1)),2,2),index((GoogleFinance(""krx:""&$C$3, ""price"", $J$1-1)),2,2))"),7430) -> 7430 | K2: =E4+H4 -> #VALUE! | L2: =Y6 -> #VALUE! | N2: =D4/G2-1+G4/G2-1 -> #VALUE! | P2: Fwd | Q2: 24-25평균 | R2: =[1]Src!CO5 -> 801.31 | S2: =[1]Src!CP5 -> 731.6 | T2: =[1]Src!CQ5 -> 921 | U2: =[1]Src!CR5 -> - | V2: =V1 -> #VALUE! | W2: EPS(원) | X2: =VLOOKUP($W$2,[1]Src!$CW$13:$DC$34,AB1,0) -> EPS(원) | Y2: =VLOOKUP($W$2,[1]Src!$CW$13:$DC$34,AC1,0) -> 233.48 | Z2: =VLOOKUP($W$2,[1]Src!$CW$13:$DC$34,AD1,0) -> 302 | AA2: =VLOOKUP($W$2,[1]Src!$CW$13:$DC$34,AE1,0) -> - | AG2: 0.9 | AH2: =2-AG2 -> 1.1 | AJ2: 매출액 | AK2: =[1]①DATA!E23 -> 10.78 | AL2: =[1]①DATA!F23 -> 31.61 | AM2: =[1]①DATA!G23 -> 7.59 | AN2: =[1]①DATA!H23 -> 8.75 | AO2: =[1]①DATA!I23 -> 40.07 | AP2: =[1]①DATA!J23 -> 31.89 | AQ2: =[1]①DATA!K23 -> -14.27 | AR2: =[1]①DATA!L23 -> 11.18
C3: =VLOOKUP(C1,[1]종목코드!$B:$N,13,0) -> 173130 | D3: TOP | E3: 수익률 | F3: 배당율 | G3: BASE | H3: 방어율 | I3: 배당율 | J3: 지표1 | K3: 선택값 | L3: T | M3: YOY | N3: EPS조정 | O3: 지표2 | P3: T | Q3: B | R3: 키워드 | S3: 번호 | T3: 투자포인트 | U3: 시점 | V3: 리스크 | W3: 종합현황 | X3: 비고 | Y3: 시나리오1 | Z3: 시나리오2 | AA3: 시나리오3 | AG3: *B 3,4Q비중 | AJ3: 이익 | AK3: =[1]①DATA!E24 -> -11.43 | AL3: =[1]①DATA!F24 -> 0 | AM3: =[1]①DATA!G24 -> 96.77 | AN3: =[1]①DATA!H24 -> -4.92 | AO3: =[1]①DATA!I24 -> 46.55 | AP3: =[1]①DATA!J24 -> 64.71 | AQ3: =[1]①DATA!K24 -> -23.57 | AR3: =[1]①DATA!L24 -> 95.12
B4: SCN1 기본 | C4: EPS Md * PE Md | D4: =$K4*$P4 -> #VALUE! | E4: =D4/$D$2-1 -> #VALUE! | F4: =[1]배당!$T$2/D4 -> #VALUE! | G4: =$K4*$Q4 -> #VALUE! | H4: =G4/$D$2-1 -> #VALUE! | I4: =[1]배당!$T$2/G4 -> #VALUE! | J4: EPS | K4: =L4 -> #VALUE! | L4: =AVERAGE($V$2)*N4 -> #VALUE! | M4: =L4/$Y$7*100-100 -> #VALUE! | N4: 1 | O4: P/E (Fwd) | P4: 10.3 | Q4: 6 | S4: 1 | U4: 현재P/E 12MF | W4: =[1]ROE!C15 -> 1 | Y4: ver.B用 | Z4: =SUM(X2:Z2) -> 535.48 | AB4: *B 90% 보수적 적용하기 | AD4: 1 | AF4: 2 | AJ4: 3 | AK4: {=INDEX($D$11:$D$223,$AJ$4)} -> #VALUE! | AL4: =AJ7=Y6 -> #VALUE!
B5: SCN2 양호 | C5: EPS Md * PE Mx | D5: =$K5*$P5 -> #VALUE! | E5: =D5/$D$2-1 -> #VALUE! | F5: =[1]배당!$T$2/D5 -> #VALUE! | G5: =$K5*$Q5 -> #VALUE! | H5: =G5/$D$2-1 -> #VALUE! | I5: =[1]배당!$T$2/G5 -> #VALUE! | J5: EPS | K5: =L5 -> #VALUE! | L5: =AVERAGE($V$2)*N5 -> #VALUE! | M5: =L5/$Y$7*100-100 -> #VALUE! | N5: 1 | O5: P/E (Fwd) | P5: 12 | Q5: 6 | S5: 2 | U5: =D2/V2 -> #VALUE! | V5: 분기 | W5: 예상EPS | X5: YOY | Y5: 연간 EPS | Z5: YOY | AA5: 컨센대비 | AB5: CAGR | AC5: 분기 | AD5: B.예상EPS | AE5: B구성비 | AF5: A.예상EPS | AG5: A예상할증 | AH5: A'24EPS | AJ5: CAGR(Yrs) | AL5: *A 사업보고서 | AN5: =AN6/AN10-1 -> #VALUE! | AO5: =AO6/AO10-1 -> #VALUE! | AP5: =AP6/AP10-1 -> #VALUE!
B6: SCN3 실망 | C6: EPS Mn * PE Mn | D6: =$K6*$P6 -> #VALUE! | E6: =D6/$D$2-1 -> #VALUE! | F6: =[1]배당!$T$2/D6 -> #VALUE! | G6: =$K6*$Q6 -> #VALUE! | H6: =G6/$D$2-1 -> #VALUE! | I6: =[1]배당!$T$2/G6 -> #VALUE! | J6: EPS | K6: =L6 -> #VALUE! | L6: =AVERAGE($V$2)*N6 -> #VALUE! | M6: =L6/$Y$7*100-100 -> #VALUE! | N6: 0.9 | O6: P/E (Fwd) | P6: 8.5 | Q6: 5 | S6: 3 | T6: EPS '25 | U6: =SUM(W10:W13) -> #VALUE! | V6: =IF(INT(MID(V7,4,1))<4,INT(LEFT(V7,2))&"."&INT(MID(V7,4,1))+1&"Q",INT(LEFT(V7,2))+1&"."&INT(MID(V7,4,1))-3&"Q") -> #VALUE! | W6: =VLOOKUP(V6,$AC$6:$AI$144,W$4*2,0) -> #VALUE! | X6: =W6/W10-1 -> #VALUE! | Y6: =SUM(W14:W17) -> #VALUE! | Z6: =AK7 -> #VALUE! | AA6: =Y6/S2 -> #VALUE! | AB6: =AB7*AB8 -> 0 | AC6: =IF(INT(MID(AC7,4,1))<4,INT(LEFT(AC7,2))&"."&INT(MID(AC7,4,1))+1&"Q",INT(LEFT(AC7,2))+1&"."&INT(MID(AC7,4,1))-3&"Q") -> #VALUE! | AD6: =AD10*(1+$AB$11) -> #VALUE! | AE6: =AD6/$Y$7 -> #VALUE! | AF6: =$U$2*AG6*AF10/SUM($AF$10:$AF$13) -> #VALUE! | AG6: 0.9 | AI6: 26 | AJ6: =Y11 -> #VALUE! | AK6: =Z11 -> #VALUE! | AL6: =AL9 -> 분기 | AP6: =AR6*AN6 -> 0 | AQ6: =AQ10 -> 0.73809524 | AR6: =AR10 -> 5.7777778
B7: SCN4 최상 | C7: EPS Mx * PE Mx | D7: =$K7*$P7 -> #VALUE! | E7: =D7/$D$2-1 -> #VALUE! | F7: =[1]배당!$T$2/D7 -> #VALUE! | G7: =$K7*$Q7 -> #VALUE! | H7: =G7/$D$2-1 -> #VALUE! | I7: =[1]배당!$T$2/G7 -> #VALUE! | J7: EPS | K7: =L7 -> #VALUE! | L7: =AVERAGE($V$2)*N7 -> #VALUE! | M7: =L7/$Y$7*100-100 -> #VALUE! | N7: 1.1 | O7: P/E (Fwd) | P7: 15 | Q7: =Q5 -> 6 | S7: 4 | T7: '24 | U7: =SUM(W14:W17) -> #VALUE! | V7: =IF(INT(MID(V8,4,1))<4,INT(LEFT(V8,2))&"."&INT(MID(V8,4,1))+1&"Q",INT(LEFT(V8,2))+1&"."&INT(MID(V8,4,1))-3&"Q") -> #VALUE! | W7: =VLOOKUP(V7,$AC$6:$AI$144,W$4*2,0) -> #VALUE! | X7: =W7/W11-1 -> #VALUE! | Y7: =SUM(W10:W13) -> #VALUE! | Z7: =Y7/Y6-1 -> #VALUE! | AA7: =Y7/T2 -> #VALUE! | AC7: =IF(INT(MID(AC8,4,1))<4,INT(LEFT(AC8,2))&"."&INT(MID(AC8,4,1))+1&"Q",INT(LEFT(AC8,2))+1&"."&INT(MID(AC8,4,1))-3&"Q") -> #VALUE! | AD7: =AD11*(1+$AB$11) -> #VALUE! | AE7: =AD7/$Y$7 -> #VALUE! | AF7: =$U$2*AG7*AF11/SUM($AF$10:$AF$13) -> #VALUE! | AG7: 0.9 | AI7: =AI6-1 -> 25 | AJ7: {=INDEX($L$11:$L$223,$AJ$4)} -> #VALUE! | AK7: =($AJ$7/AJ8)^(1/(ROW(AJ8)-ROW($AJ$7))) - 1 -> #VALUE! | AL7: *A 컨센서스 값기준 | AR7: 주식수
C8: Fd PER 모델 | V8: =IF(INT(MID(V9,4,1))<4,INT(LEFT(V9,2))&"."&INT(MID(V9,4,1))+1&"Q",INT(LEFT(V9,2))+1&"."&INT(MID(V9,4,1))-3&"Q") -> #VALUE! | W8: =VLOOKUP(V8,$AC$6:$AI$144,W$4*2,0) -> #VALUE! | X8: =W8/W12-1 -> #VALUE! | Y8: =SUM(W6:W9) -> #VALUE! | Z8: =Y8/Y7-1 -> #VALUE! | AA8: =Y8/U2 -> #VALUE! | AB8: 1 | AC8: =IF(INT(MID(AC9,4,1))<4,INT(LEFT(AC9,2))&"."&INT(MID(AC9,4,1))+1&"Q",INT(LEFT(AC9,2))+1&"."&INT(MID(AC9,4,1))-3&"Q") -> #VALUE! | AD8: =AD12*(1+$AB$11) -> #VALUE! | AE8: =AD8/$Y$7 -> #VALUE! | AF8: =$U$2*AG8*AF12/SUM($AF$10:$AF$13) -> #VALUE! | AG8: 0.9 | AH8: =SUM(AF10:AF13) -> #VALUE! | AI8: =AI7-1 -> 24 | AJ8: {=INDEX($L$11:$L$223,$AJ$4+4)} -> 731 | AK8: =($AJ$7/AJ9)^(1/(ROW(AJ9)-ROW($AJ$7))) - 1 -> #VALUE! | AL8: =D14 -> #VALUE! | AM8: =VLOOKUP(AM$9,[1]Src!$CW$13:$DC$34,$AE$1,0) -> #N/A | AN8: =VLOOKUP(AN$9,[1]Src!$CW$13:$DC$34,$AE$1,0) -> #N/A | AO8: =VLOOKUP(AO$9,[1]Src!$CW$13:$DC$34,$AE$1,0) -> - | AP8: =VLOOKUP(AP$9,[1]Src!$CW$13:$DC$34,$AE$1,0) -> - | AQ8: 예상EPS | AR8: =AO14/AP14 -> 0.12875536
C9: =C1 -> 오파스넷 | D9: =VLOOKUP(C9,[1]종목코드!$B:$N,13,0) -> 173130 | E9: 고가 | F9: 저가 | G9: 종가 | H9: EPS Q | I9: EPS Y | J9: P/E (Fd) | L9: EPS Y | M9: P/E (TTM) | O9: EPS Y | P9: P/E (Y0) | R9: EPS Y | S9: P/E (Y1) | U9: EPS YOY | V9: =IF(INT(MID(V10,4,1))<4,INT(LEFT(V10,2))&"."&INT(MID(V10,4,1))+1&"Q",INT(LEFT(V10,2))+1&"."&INT(MID(V10,4,1))-3&"Q") -> #VALUE! | W9: =VLOOKUP(V9,$AC$6:$AI$144,W$4*2,0) -> #VALUE! | X9: =W9/W13-1 -> #VALUE! | AB9: =Z7 -> #VALUE! | AC9: =IF(INT(MID(AC10,4,1))<4,INT(LEFT(AC10,2))&"."&INT(MID(AC10,4,1))+1&"Q",INT(LEFT(AC10,2))+1&"."&INT(MID(AC10,4,1))-3&"Q") -> #VALUE! | AD9: =AD13*(1+$AB$11) -> #VALUE! | AE9: =AD9/$Y$7 -> #VALUE! | AF9: =$U$2*AG9*AF13/SUM($AF$10:$AF$13) -> #VALUE! | AG9: 0.9 | AH9: =AH8/#REF!-1 -> #VALUE! | AI9: =AI8-1 -> 23 | AJ9: {=INDEX($L$11:$L$223,$AJ$4+8)} -> 801 | AK9: =($AJ$7/AJ10)^(1/(ROW(AJ10)-ROW($AJ$7))) - 1 -> #VALUE! | AL9: 분기 | AM9: =[1]Src!H1 -> 매출액 | AN9: =[1]Src!I1 -> 영업이익 | AO9: 지배주주순이익 | AP9: EPS(원) | AQ9: %순이익 | AR9: %EPS
I10: (Fd 4Q) | J10: TOP | K10: BASE | L10: TTM | M10: TOP | N10: BASE | O10: Y0 | P10: TOP | Q10: BASE | R10: Y1 | S10: TOP | T10: BASE | V10: =IF(INT(MID(V11,4,1))<4,INT(LEFT(V11,2))&"."&INT(MID(V11,4,1))+1&"Q",INT(LEFT(V11,2))+1&"."&INT(MID(V11,4,1))-3&"Q") -> #VALUE! | W10: =VLOOKUP(V10,$AC$6:$AI$144,W$4*2,0) -> #VALUE! | X10: =W10/W14-1 -> #VALUE! | Y10: 4Q 누계 | AB10: 1 | AC10: =IF(INT(MID(AC11,4,1))<4,INT(LEFT(AC11,2))&"."&INT(MID(AC11,4,1))+1&"Q",INT(LEFT(AC11,2))+1&"."&INT(MID(AC11,4,1))-3&"Q") -> #VALUE! | AD10: 302 | AE10: =AD10/$Y$7 -> #VALUE! | AF10: =AG10*AA2 -> #VALUE! | AG10: 0.95 | AI10: =AI9-1 -> 22 | AJ10: {=INDEX($L$11:$L$223,$AJ$4+12)} -> 465 | AK10: =($AJ$7/AJ11)^(1/(ROW(AJ11)-ROW($AJ$7))) - 1 -> #VALUE! | AL10: 25.2Q추정 | AN10: =AP10/AR10 -> #VALUE! | AO10: =AN10*AQ10 -> #VALUE! | AP10: =W12 -> #VALUE! | AQ10: =AVERAGE(AQ16,AQ24,AQ28) -> 0.73809524 | AR10: =AVERAGE(AR16,AR24,AR28) -> 5.7777778
A11: 연도 | B11: =[1]Src!S1 -> 지배주주ROE | D11: =IF(INT(MID(D12,4,1))<4,INT(LEFT(D12,2))&"."&INT(MID(D12,4,1))+1&"Q",INT(LEFT(D12,2))+1&"."&INT(MID(D12,4,1))-3&"Q") -> #VALUE! | E11: =D2 -> 7150 | F11: =D2 -> 7150 | G11: =D2 -> 7150 | H11: =VLOOKUP($D11,$V$6:$W$17,2,0) -> #VALUE! | J11: =$D$2/I11 -> #DIV/0! | L11: =SUM(H11:H14) -> #VALUE! | M11: =$D$2/L11 -> #VALUE! | O11: =R17 -> #VALUE! | P11: =MAX(E11:E12)/SUM($H11:$H14) -> #VALUE! | Q11: =MIN(F11:F12)/SUM($H11:$H14) -> #VALUE! | V11: =IF(INT(MID(V12,4,1))<4,INT(LEFT(V12,2))&"."&INT(MID(V12,4,1))+1&"Q",INT(LEFT(V12,2))+1&"."&INT(MID(V12,4,1))-3&"Q") -> #VALUE! | W11: =VLOOKUP(V11,$AC$6:$AI$144,W$4*2,0) -> #VALUE! | X11: =W11/W15-1 -> #VALUE! | Y11: =SUM(W10:W13) -> #VALUE! | Z11: =Y11/Y12-1 -> #VALUE! | AB11: =AB9*AB12 -> #VALUE! | AC11: =IF(INT(MID(AC12,4,1))<4,INT(LEFT(AC12,2))&"."&INT(MID(AC12,4,1))+1&"Q",INT(LEFT(AC12,2))+1&"."&INT(MID(AC12,4,1))-3&"Q") -> #VALUE! | AD11: =IFERROR(VLOOKUP($AC11,$D$12:$T$56,5,0),"") | AE11: =AD11/$Y$7 -> #VALUE! | AF11: =IFERROR(VLOOKUP($AC11,$D$12:$T$56,5,0),"") | AG11: 0.95 | AI11: =AC16 -> #VALUE! | AJ11: {=INDEX($L$11:$L$223,$AJ$4+16)} -> 478 | AK11: =($AJ$7/AJ12)^(1/(ROW(AJ12)-ROW($AJ$7))) - 1 -> #VALUE!
A12: =LEFT(D12,2) -> #VALUE! | B12: =[1]Src!S2 -> 0 | C12: =[1]Src!B2 -> 46024 | D12: =MID(C12,3,2)&"."&ROUNDUP(MID(C12,6,2)/3,0)&"Q" -> #VALUE! | E12: =IFERROR(VLOOKUP($C12,[1]Src!$B:$AI,3,0),"") -> 7930 | F12: =IFERROR(VLOOKUP($C12,[1]Src!$B:$AI,4,0),"") -> 6100 | G12: =IFERROR(VLOOKUP($C12,[1]Src!$B:$AI,5,0),"") -> 7380 | H12: =IF(VLOOKUP($C12,[1]Src!$B:$AI,10,0)=0,VLOOKUP($D12,$V$6:$W$17,2,0),"확인") -> #VALUE! | I12: =SUM(OFFSET(INDEX(V:V, MATCH(D12, V:V, 0)), -3, 1, 4, 1)) -> #VALUE! | J12: =E12/$I12 -> #VALUE! | K12: =F12/$I12 -> #VALUE! | L12: =SUM(H12:H15) -> #VALUE! | M12: =E12/SUM($H12:$H15) -> #VALUE! | N12: =F12/SUM($H12:$H15) -> #VALUE! | P12: =MAX(E12:E13)/SUM($H12:$H15) -> #VALUE! | Q12: =MIN(F12:F13)/SUM($H12:$H15) -> #VALUE! | R12: =SUM(W6:W9) -> #VALUE! | S12: =MAX(E12:E15)/$R12 -> #VALUE! | T12: =MIN(F12:F15)/$R12 -> #VALUE! | V12: =IF(INT(MID(V13,4,1))<4,INT(LEFT(V13,2))&"."&INT(MID(V13,4,1))+1&"Q",INT(LEFT(V13,2))+1&"."&INT(MID(V13,4,1))-3&"Q") -> #VALUE! | W12: =VLOOKUP(V12,$AC$6:$AI$144,W$4*2,0) -> #VALUE! | X12: =W12/W16-1 -> #VALUE! | Y12: =SUM(W14:W17) -> #VALUE! | AB12: 0.7 | AC12: =IF(INT(MID(AC13,4,1))<4,INT(LEFT(AC13,2))&"."&INT(MID(AC13,4,1))+1&"Q",INT(LEFT(AC13,2))+1&"."&INT(MID(AC13,4,1))-3&"Q") -> #VALUE! | AD12: =IFERROR(VLOOKUP($AC12,$D$12:$T$56,5,0),"") | AE12: =AD12/$Y$7 -> #VALUE! | AF12: =IFERROR(VLOOKUP($AC12,$D$12:$T$56,5,0),"") | AG12: 1 | AH12: =SUM(AF14:AF17) -> 0 | AI12: =[1]ROE!U171 -> 229.89 | AJ12: {=INDEX($L$11:$L$223,$AJ$4+20)} -> 462 | AK12: =($AJ$7/AJ13)^(1/(ROW(AJ13)-ROW($AJ$7))) - 1 -> #VALUE! | AL12: =MID(C12,3,2)&"."&ROUNDUP(MID(C12,6,2)/3,0)&"Q" -> #VALUE! | AM12: =IFERROR(VLOOKUP($C12,[1]Src!$B$2:$AI$130,7,0),"") -> 0 | AN12: =IFERROR(VLOOKUP($C12,[1]Src!$B$2:$AI$130,8,0),"") -> 0 | AO12: =IFERROR(VLOOKUP($C12,[1]Src!$B$2:$AI$130,9,0),"") -> 0 | AP12: =IFERROR(VLOOKUP($C12,[1]Src!$B$2:$AI$130,10,0),"") -> 0 | AQ12: =AO12/$AN12 -> #DIV/0! | AR12: =AP12/$AN12 -> #DIV/0!
A13: =LEFT(D13,2) -> #VALUE! | B13: =[1]Src!S3 -> 0 | C13: =[1]Src!B3 -> 45931 | D13: =MID(C13,3,2)&"."&ROUNDUP(MID(C13,6,2)/3,0)&"Q" -> #VALUE! | E13: =IFERROR(VLOOKUP($C13,[1]Src!$B:$AI,3,0),"") -> 7250 | F13: =IFERROR(VLOOKUP($C13,[1]Src!$B:$AI,4,0),"") -> 6060 | G13: =IFERROR(VLOOKUP($C13,[1]Src!$B:$AI,5,0),"") -> 6640 | H13: =IF(VLOOKUP($C13,[1]Src!$B:$AI,10,0)="",VLOOKUP($D13,$V$6:$W$17,2,0),"확인") -> #VALUE! | I13: =SUM(OFFSET(INDEX(V:V, MATCH(D13, V:V, 0)), -3, 1, 4, 1)) -> #VALUE! | J13: =E13/$I13 -> #VALUE! | K13: =F13/$I13 -> #VALUE! | L13: =SUM(H13:H16) -> #VALUE! | M13: =E13/SUM($H13:$H16) -> #VALUE! | N13: =F13/SUM($H13:$H16) -> #VALUE! | P13: =MAX(E13:E14)/SUM($H13:$H16) -> #VALUE! | Q13: =MIN(F13:F14)/SUM($H13:$H16) -> #VALUE! | R13: =SUM(OFFSET(INDEX(V:V, MATCH(D13, V:V, 0)), -4, 1, 4, 1)) -> #VALUE! | S13: =MAX(E13:E16)/$R13 -> #VALUE! | T13: =MIN(F13:F16)/$R13 -> #VALUE! | U13: =INT(LEFT(D13,2)) -> #VALUE! | V13: =IF(INT(MID(V14,4,1))<4,INT(LEFT(V14,2))&"."&INT(MID(V14,4,1))+1&"Q",INT(LEFT(V14,2))+1&"."&INT(MID(V14,4,1))-3&"Q") -> #VALUE! | W13: =VLOOKUP(V13,$AC$6:$AI$144,W$4*2,0) -> #VALUE! | X13: =W13/W17-1 -> #VALUE! | AC13: =IF(INT(MID(AC14,4,1))<4,INT(LEFT(AC14,2))&"."&INT(MID(AC14,4,1))+1&"Q",INT(LEFT(AC14,2))+1&"."&INT(MID(AC14,4,1))-3&"Q") -> #VALUE! | AD13: =IFERROR(VLOOKUP($AC13,$D$12:$T$56,5,0),"") | AE13: =AD13/$Y$7 -> #VALUE! | AF13: =IFERROR(VLOOKUP($AC13,$D$12:$T$56,5,0),"") | AG13: 1 | AH13: =AH12/R2-1 -> -1 | AJ13: {=INDEX($L$11:$L$223,$AJ$4+24)} -> -909 | AK13: =($AJ$7/AJ14)^(1/(ROW(AJ14)-ROW($AJ$7))) - 1 -> #VALUE! | AL13: =MID(C13,3,2)&"."&ROUNDUP(MID(C13,6,2)/3,0)&"Q" -> #VALUE! | AM13: =IFERROR(VLOOKUP($C13,[1]Src!$B$2:$AI$130,7,0),"") -> 879 | AN13: =IFERROR(VLOOKUP($C13,[1]Src!$B$2:$AI$130,8,0),"") -> 45 | AO13: =IFERROR(VLOOKUP($C13,[1]Src!$B$2:$AI$130,9,0),"") -> 0 | AP13: =IFERROR(VLOOKUP($C13,[1]Src!$B$2:$AI$130,10,0),"") -> 0 | AQ13: =AO13/$AN13 -> 0 | AR13: =AP13/$AN13 -> 0
A14: =LEFT(D14,2) -> #VALUE! | B14: =[1]Src!S4 -> 20.62 | C14: =[1]Src!B4 -> 45839 | D14: =MID(C14,3,2)&"."&ROUNDUP(MID(C14,6,2)/3,0)&"Q" -> #VALUE! | E14: =IFERROR(VLOOKUP($C14,[1]Src!$B:$AI,3,0),"") -> 7200 | F14: =IFERROR(VLOOKUP($C14,[1]Src!$B:$AI,4,0),"") -> 6130 | G14: =IFERROR(VLOOKUP($C14,[1]Src!$B:$AI,5,0),"") -> 6290 | H14: =IFERROR(VLOOKUP($C14,[1]Src!$B:$AI,10,0),"") -> 233 | I14: =SUM(OFFSET(INDEX(V:V, MATCH(D14, V:V, 0)), -3, 1, 4, 1)) -> #VALUE! | J14: =E14/$I14 -> #VALUE! | K14: =F14/$I14 -> #VALUE! | L14: =SUM(H14:H17) -> 1108 | M14: =E14/SUM($H14:$H17) -> 6.4981949 | N14: =F14/SUM($H14:$H17) -> 5.532491 | P14: =MAX(E14:E15)/SUM($H14:$H17) -> 10.315884 | Q14: =MIN(F14:F15)/SUM($H14:$H17) -> 5.0361011 | R14: =SUM(OFFSET(INDEX(V:V, MATCH(D14, V:V, 0)), -4, 1, 4, 1)) -> #VALUE! | S14: =MAX(E14:E17)/$R14 -> #VALUE! | T14: =MIN(F14:F17)/$R14 -> #VALUE! | V14: =IF(INT(MID(V15,4,1))<4,INT(LEFT(V15,2))&"."&INT(MID(V15,4,1))+1&"Q",INT(LEFT(V15,2))+1&"."&INT(MID(V15,4,1))-3&"Q") -> #VALUE! | W14: =VLOOKUP(V14,$AC$6:$AI$144,W$4*2,0) -> #VALUE! | X14: =W14/H19-1 -> #VALUE! | AC14: =IF(INT(MID(AC15,4,1))<4,INT(LEFT(AC15,2))&"."&INT(MID(AC15,4,1))+1&"Q",INT(LEFT(AC15,2))+1&"."&INT(MID(AC15,4,1))-3&"Q") -> #VALUE! | AD14: =IFERROR(VLOOKUP($AC14,$D$12:$T$56,5,0),"") | AE14: =$AD$18/(4-$AC$18)*AH2 -> #VALUE! | AF14: =IFERROR(VLOOKUP($AC14,$D$12:$T$56,5,0),"") | AG14: 1 | AH14: A'25EPS | AJ14: {=INDEX($L$11:$L$223,$AJ$4+28)} -> 182 | AK14: =($AJ$7/AJ15)^(1/(ROW(AJ15)-ROW($AJ$7))) - 1 -> #VALUE! | AL14: =MID(C14,3,2)&"."&ROUNDUP(MID(C14,6,2)/3,0)&"Q" -> #VALUE! | AM14: =IFERROR(VLOOKUP($C14,[1]Src!$B$2:$AI$130,7,0),"") -> 428 | AN14: =IFERROR(VLOOKUP($C14,[1]Src!$B$2:$AI$130,8,0),"") -> 34 | AO14: =IFERROR(VLOOKUP($C14,[1]Src!$B$2:$AI$130,9,0),"") -> 30 | AP14: =IFERROR(VLOOKUP($C14,[1]Src!$B$2:$AI$130,10,0),"") -> 233 | AQ14: =AO14/$AN14 -> 0.88235294 | AR14: =AP14/$AN14 -> 6.8529412
A15: =LEFT(D15,2) -> #VALUE! | B15: =[1]Src!S5 -> 33.1 | C15: =[1]Src!B5 -> 45748 | D15: =MID(C15,3,2)&"."&ROUNDUP(MID(C15,6,2)/3,0)&"Q" -> #VALUE! | E15: =IFERROR(VLOOKUP($C15,[1]Src!$B:$AI,3,0),"") -> 11430 | F15: =IFERROR(VLOOKUP($C15,[1]Src!$B:$AI,4,0),"") -> 5580 | G15: =IFERROR(VLOOKUP($C15,[1]Src!$B:$AI,5,0),"") -> 6770 | H15: =IFERROR(VLOOKUP($C15,[1]Src!$B:$AI,10,0),"") -> 351 | I15: =SUM(OFFSET(INDEX(V:V, MATCH(D15, V:V, 0)), -3, 1, 4, 1)) -> #VALUE! | J15: =E15/$I15 -> #VALUE! | K15: =F15/$I15 -> #VALUE! | L15: =SUM(H15:H18) -> 1004 | M15: =E15/SUM($H15:$H18) -> 11.384462 | N15: =F15/SUM($H15:$H18) -> 5.5577689 | O15: =SUM(H15:H18) -> 1004 | P15: =MAX(E15:E16)/SUM($H15:$H18) -> 11.384462 | Q15: =MIN(F15:F16)/SUM($H15:$H18) -> 5.5577689 | R15: =SUM(OFFSET(INDEX(V:V, MATCH(D15, V:V, 0)), -4, 1, 4, 1)) -> #VALUE! | S15: =MAX(E15:E18)/$R15 -> #VALUE! | T15: =MIN(F15:F18)/$R15 -> #VALUE! | V15: =IF(INT(MID(V16,4,1))<4,INT(LEFT(V16,2))&"."&INT(MID(V16,4,1))+1&"Q",INT(LEFT(V16,2))+1&"."&INT(MID(V16,4,1))-3&"Q") -> #VALUE! | W15: =VLOOKUP(V15,$AC$6:$AI$144,W$4*2,0) -> #VALUE! | X15: =W15/H20-1 -> #VALUE! | AC15: =IF(INT(MID(AC16,4,1))<4,INT(LEFT(AC16,2))&"."&INT(MID(AC16,4,1))+1&"Q",INT(LEFT(AC16,2))+1&"."&INT(MID(AC16,4,1))-3&"Q") -> #VALUE! | AD15: =IFERROR(VLOOKUP($AC15,$D$12:$T$56,5,0),"") | AE15: =$AD$18/(4-$AC$18)*AG2 -> #VALUE! | AF15: =IFERROR(VLOOKUP($AC15,$D$12:$T$56,5,0),"") | AG15: 1 | AH15: =SUM(AF10:AF13) -> #VALUE! | AJ15: {=INDEX($L$11:$L$223,$AJ$4+32)} -> 95 | AK15: =($AJ$7/AJ16)^(1/(ROW(AJ16)-ROW($AJ$7))) - 1 -> #VALUE! | AL15: =MID(C15,3,2)&"."&ROUNDUP(MID(C15,6,2)/3,0)&"Q" -> #VALUE! | AM15: =IFERROR(VLOOKUP($C15,[1]Src!$B$2:$AI$130,7,0),"") -> 582 | AN15: =IFERROR(VLOOKUP($C15,[1]Src!$B$2:$AI$130,8,0),"") -> 56 | AO15: =IFERROR(VLOOKUP($C15,[1]Src!$B$2:$AI$130,9,0),"") -> 46 | AP15: =IFERROR(VLOOKUP($C15,[1]Src!$B$2:$AI$130,10,0),"") -> 351 | AQ15: =AO15/$AN15 -> 0.82142857 | AR15: =AP15/$AN15 -> 6.2678571
A16: =LEFT(D16,2) -> #VALUE! | B16: =[1]Src!S6 -> 3.58 | C16: =[1]Src!B6 -> 45659 | D16: =MID(C16,3,2)&"."&ROUNDUP(MID(C16,6,2)/3,0)&"Q" -> #VALUE! | E16: =IFERROR(VLOOKUP($C16,[1]Src!$B:$AI,3,0),"") -> 10050 | F16: =IFERROR(VLOOKUP($C16,[1]Src!$B:$AI,4,0),"") -> 7600 | G16: =IFERROR(VLOOKUP($C16,[1]Src!$B:$AI,5,0),"") -> 7770 | H16: =IFERROR(VLOOKUP($C16,[1]Src!$B:$AI,10,0),"") -> 37 | I16: =SUM(OFFSET(INDEX(V:V, MATCH(D16, V:V, 0)), -3, 1, 4, 1)) -> #VALUE! | J16: =E16/$I16 -> #VALUE! | K16: =F16/$I16 -> #VALUE! | L16: =SUM(H16:H19) -> 758 | M16: =E16/SUM($H16:$H19) -> 13.258575 | N16: =F16/SUM($H16:$H19) -> 10.026385 | O16: =SUM(H16:H19) -> 758 | P16: =MAX(E16:E17)/SUM($H16:$H19) -> 16.121372 | Q16: =MIN(F16:F17)/SUM($H16:$H19) -> 8.469657 | R16: =SUM(OFFSET(INDEX(V:V, MATCH(D16, V:V, 0)), -4, 1, 4, 1)) -> #VALUE! | S16: =MAX(E16:E19)/$R16 -> #VALUE! | T16: =MIN(F16:F19)/$R16 -> #VALUE! | V16: =IF(INT(MID(V17,4,1))<4,INT(LEFT(V17,2))&"."&INT(MID(V17,4,1))+1&"Q",INT(LEFT(V17,2))+1&"."&INT(MID(V17,4,1))-3&"Q") -> #VALUE! | W16: =VLOOKUP(V16,$AC$6:$AI$144,W$4*2,0) -> #VALUE! | X16: =W16/H21-1 -> #VALUE! | AC16: =IF(INT(MID(AC17,4,1))<4,INT(LEFT(AC17,2))&"."&INT(MID(AC17,4,1))+1&"Q",INT(LEFT(AC17,2))+1&"."&INT(MID(AC17,4,1))-3&"Q") -> #VALUE! | AD16: =IFERROR(VLOOKUP($AC16,$D$12:$T$56,5,0),"") | AE16: =AD16/$Y$6 -> #VALUE! | AF16: =IFERROR(VLOOKUP($AC16,$D$12:$T$56,5,0),"") | AG16: 1 | AH16: =AH15/AH12-1 -> #VALUE! | AJ16: {=INDEX($L$11:$L$223,$AJ$4+36)} -> 0 | AL16: =MID(C16,3,2)&"."&ROUNDUP(MID(C16,6,2)/3,0)&"Q" -> #VALUE! | AM16: =IFERROR(VLOOKUP($C16,[1]Src!$B$2:$AI$130,7,0),"") -> 444 | AN16: =IFERROR(VLOOKUP($C16,[1]Src!$B$2:$AI$130,8,0),"") -> 6 | AO16: =IFERROR(VLOOKUP($C16,[1]Src!$B$2:$AI$130,9,0),"") -> 5 | AP16: =IFERROR(VLOOKUP($C16,[1]Src!$B$2:$AI$130,10,0),"") -> 37 | AQ16: =AO16/$AN16 -> 0.83333333 | AR16: =AP16/$AN16 -> 6.1666667
A17: =LEFT(D17,2) -> #VALUE! | B17: =[1]Src!S7 -> 49.96 | C17: =[1]Src!B7 -> 45567 | D17: =MID(C17,3,2)&"."&ROUNDUP(MID(C17,6,2)/3,0)&"Q" -> #VALUE! | E17: =IFERROR(VLOOKUP($C17,[1]Src!$B:$AI,3,0),"") -> 12220 | F17: =IFERROR(VLOOKUP($C17,[1]Src!$B:$AI,4,0),"") -> 6420 | G17: =IFERROR(VLOOKUP($C17,[1]Src!$B:$AI,5,0),"") -> 8440 | H17: =IFERROR(VLOOKUP($C17,[1]Src!$B:$AI,10,0),"") -> 487 | I17: =SUM(H14:H17) -> 1108 | J17: =E17/$I17 -> 11.028881 | K17: =F17/$I17 -> 5.7942238 | L17: =SUM(H17:H20) -> 731 | M17: =E17/SUM($H17:$H20) -> 16.716826 | N17: =F17/SUM($H17:$H20) -> 8.7824897 | P17: =MAX(E17:E18)/SUM($H17:$H20) -> 16.716826 | Q17: =MIN(F17:F18)/SUM($H17:$H20) -> 7.8932969 | R17: =SUM(H13:H16) -> #VALUE! | S17: =MAX(E17:E20)/$R17 -> #VALUE! | T17: =MIN(F17:F20)/$R17 -> #VALUE! | U17: =INT(LEFT(D17,2)) -> #VALUE! | V17: =D20 -> #VALUE! | W17: =VLOOKUP(V17,$AC$6:$AI$144,W$4*2,0) -> #VALUE! | X17: =W17/H22-1 -> #VALUE! | AC17: =V17 -> #VALUE! | AD17: =IFERROR(VLOOKUP($AC17,$D$12:$T$56,5,0),"") | AE17: =AD17/$Y$6 -> #VALUE! | AF17: =IFERROR(VLOOKUP($AC17,$D$12:$T$56,5,0),"") | AG17: 1 | AH17: =AH15/T2 -> #VALUE! | AL17: =MID(C17,3,2)&"."&ROUNDUP(MID(C17,6,2)/3,0)&"Q" -> #VALUE! | AM17: =IFERROR(VLOOKUP($C17,[1]Src!$B$2:$AI$130,7,0),"") -> 763 | AN17: =IFERROR(VLOOKUP($C17,[1]Src!$B$2:$AI$130,8,0),"") -> 64 | AO17: =IFERROR(VLOOKUP($C17,[1]Src!$B$2:$AI$130,9,0),"") -> 64 | AP17: =IFERROR(VLOOKUP($C17,[1]Src!$B$2:$AI$130,10,0),"") -> 487 | AQ17: =AO17/$AN17 -> 1 | AR17: =AP17/$AN17 -> 7.609375
A18: =LEFT(D18,2) -> #VALUE! | B18: =[1]Src!S8 -> 14.3 | C18: =[1]Src!B8 -> 45474 | D18: =MID(C18,3,2)&"."&ROUNDUP(MID(C18,6,2)/3,0)&"Q" -> #VALUE! | E18: =IFERROR(VLOOKUP($C18,[1]Src!$B:$AI,3,0),"") -> 10430 | F18: =IFERROR(VLOOKUP($C18,[1]Src!$B:$AI,4,0),"") -> 5770 | G18: =IFERROR(VLOOKUP($C18,[1]Src!$B:$AI,5,0),"") -> 7100 | H18: =IFERROR(VLOOKUP($C18,[1]Src!$B:$AI,10,0),"") -> 129 | I18: =SUM(H15:H18) -> 1004 | J18: =E18/SUM($H15:$H18) -> 10.388446 | K18: =F18/SUM($H15:$H18) -> 5.747012 | L18: =SUM(H18:H21) -> 489 | M18: =E18/SUM($H18:$H21) -> 21.329243 | N18: =F18/SUM($H18:$H21) -> 11.799591 | P18: =MAX(E18:E19)/SUM($H18:$H21) -> 21.595092 | Q18: =MIN(F18:F19)/SUM($H18:$H21) -> 11.799591 | R18: =SUM(H14:H17) -> 1108 | S18: =MAX(E18:E21)/SUM($H14:$H17) -> 14.997292 | T18: =MIN(F18:F21)/SUM($H14:$H17) -> 5.2075812 | V18: 밸류에이션 코멘트 | AC18: 2 | AD18: =1-AE17-AE16 -> #VALUE! | AE18: 4Q모델링 : | AF18: =[1]my리포트!T366 -> #REF! | AL18: =MID(C18,3,2)&"."&ROUNDUP(MID(C18,6,2)/3,0)&"Q" -> #VALUE! | AM18: =IFERROR(VLOOKUP($C18,[1]Src!$B$2:$AI$130,7,0),"") -> 444 | AN18: =IFERROR(VLOOKUP($C18,[1]Src!$B$2:$AI$130,8,0),"") -> 25 | AO18: =IFERROR(VLOOKUP($C18,[1]Src!$B$2:$AI$130,9,0),"") -> 17 | AP18: =IFERROR(VLOOKUP($C18,[1]Src!$B$2:$AI$130,10,0),"") -> 129 | AQ18: =AO18/$AN18 -> 0.68 | AR18: =AP18/$AN18 -> 5.16
A19: =LEFT(D19,2) -> #VALUE! | B19: =[1]Src!S9 -> 12 | C19: =[1]Src!B9 -> 45383 | D19: =MID(C19,3,2)&"."&ROUNDUP(MID(C19,6,2)/3,0)&"Q" -> #VALUE! | E19: =IFERROR(VLOOKUP($C19,[1]Src!$B:$AI,3,0),"") -> 10560 | F19: =IFERROR(VLOOKUP($C19,[1]Src!$B:$AI,4,0),"") -> 7120 | G19: =IFERROR(VLOOKUP($C19,[1]Src!$B:$AI,5,0),"") -> 8690 | H19: =IFERROR(VLOOKUP($C19,[1]Src!$B:$AI,10,0),"") -> 105 | I19: =SUM(H16:H19) -> 758 | J19: =E19/SUM($H16:$H19) -> 13.931398 | K19: =F19/SUM($H16:$H19) -> 9.3931398 | L19: =SUM(H19:H22) -> 527 | M19: =E19/SUM($H19:$H22) -> 20.037951 | N19: =F19/SUM($H19:$H22) -> 13.510436 | O19: =SUM(H19:H22) -> 527 | P19: =MAX(E19:E20)/SUM($H19:$H22) -> 23.149905 | Q19: =MIN(F19:F20)/SUM($H19:$H22) -> 13.510436 | R19: =SUM(H15:H18) -> 1004 | S19: =MAX(E19:E22)/SUM($H15:$H18) -> 18.062749 | T19: =MIN(F19:F22)/SUM($H15:$H18) -> 7.0916335 | AC19: =D20 -> #VALUE! | AJ19: EPS 모델링 | AL19: =MID(C19,3,2)&"."&ROUNDUP(MID(C19,6,2)/3,0)&"Q" -> #VALUE! | AM19: =IFERROR(VLOOKUP($C19,[1]Src!$B$2:$AI$130,7,0),"") -> 390 | AN19: =IFERROR(VLOOKUP($C19,[1]Src!$B$2:$AI$130,8,0),"") -> 17 | AO19: =IFERROR(VLOOKUP($C19,[1]Src!$B$2:$AI$130,9,0),"") -> 14 | AP19: =IFERROR(VLOOKUP($C19,[1]Src!$B$2:$AI$130,10,0),"") -> 105 | AQ19: =AO19/$AN19 -> 0.82352941 | AR19: =AP19/$AN19 -> 6.1764706
A20: =LEFT(D20,2) -> #VALUE! | B20: =[1]Src!S10 -> 1.16 | C20: =[1]Src!B10 -> 45293 | D20: =MID(C20,3,2)&"."&ROUNDUP(MID(C20,6,2)/3,0)&"Q" -> #VALUE! | E20: =IFERROR(VLOOKUP($C20,[1]Src!$B:$AI,3,0),"") -> 12200 | F20: =IFERROR(VLOOKUP($C20,[1]Src!$B:$AI,4,0),"") -> 8220 | G20: =IFERROR(VLOOKUP($C20,[1]Src!$B:$AI,5,0),"") -> 8590 | H20: =IFERROR(VLOOKUP($C20,[1]Src!$B:$AI,10,0),"") -> 10 | I20: =SUM(H17:H20) -> 731 | J20: =E20/SUM($H17:$H20) -> 16.689466 | K20: =F20/SUM($H17:$H20) -> 11.24487 | L20: =SUM(H20:H23) -> 687 | M20: =E20/SUM($H20:$H23) -> 17.75837 | N20: =F20/SUM($H20:$H23) -> 11.965066 | O20: =SUM(H20:H23) -> 687 | P20: =MAX(E20:E21)/SUM($H20:$H23) -> 24.187773 | Q20: =MIN(F20:F21)/SUM($H20:$H23) -> 11.965066 | R20: =SUM(H16:H19) -> 758 | S20: =MAX(E20:E23)/SUM($H16:$H19) -> 23.924802 | T20: =MIN(F20:F23)/SUM($H16:$H19) -> 10.385224 | AC20: =D21 -> #VALUE! | AJ20: 24년 | AK20: =[1]my리포트!AE378 -> #REF! | AL20: =MID(C20,3,2)&"."&ROUNDUP(MID(C20,6,2)/3,0)&"Q" -> #VALUE! | AM20: =IFERROR(VLOOKUP($C20,[1]Src!$B$2:$AI$130,7,0),"") -> 331 | AN20: =IFERROR(VLOOKUP($C20,[1]Src!$B$2:$AI$130,8,0),"") -> 1 | AO20: =IFERROR(VLOOKUP($C20,[1]Src!$B$2:$AI$130,9,0),"") -> 1 | AP20: =IFERROR(VLOOKUP($C20,[1]Src!$B$2:$AI$130,10,0),"") -> 10 | AQ20: =AO20/$AN20 -> 1 | AR20: =AP20/$AN20 -> 10
A21: =LEFT(D21,2) -> #VALUE! | B21: =[1]Src!S11 -> 28.77 | C21: =[1]Src!B11 -> 45203 | D21: =MID(C21,3,2)&"."&ROUNDUP(MID(C21,6,2)/3,0)&"Q" -> #VALUE! | E21: =IFERROR(VLOOKUP($C21,[1]Src!$B:$AI,3,0),"") -> 16617 | F21: =IFERROR(VLOOKUP($C21,[1]Src!$B:$AI,4,0),"") -> 10580 | G21: =IFERROR(VLOOKUP($C21,[1]Src!$B:$AI,5,0),"") -> 11720 | H21: =IFERROR(VLOOKUP($C21,[1]Src!$B:$AI,10,0),"") -> 245 | I21: =SUM(H18:H21) -> 489 | J21: =E21/SUM($H18:$H21) -> 33.981595 | K21: =F21/SUM($H18:$H21) -> 21.635992 | L21: =SUM(H21:H24) -> 801 | M21: =E21/SUM($H21:$H24) -> 20.745318 | N21: =F21/SUM($H21:$H24) -> 13.208489 | P21: =MAX(E21:E22)/SUM($H21:$H24) -> 22.640449 | Q21: =MIN(F21:F22)/SUM($H21:$H24) -> 11.154806 | R21: =SUM(H17:H20) -> 731 | S21: =MAX(E21:E24)/SUM($H17:$H20) -> 24.808482 | T21: =MIN(F21:F24)/SUM($H17:$H20) -> 9.6374829 | U21: =INT(LEFT(D21,2)) -> #VALUE! | AC21: =D22 -> #VALUE! | AJ21: 25년 | AK21: =[1]my리포트!AF378 -> #REF! | AL21: =MID(C21,3,2)&"."&ROUNDUP(MID(C21,6,2)/3,0)&"Q" -> #VALUE! | AM21: =IFERROR(VLOOKUP($C21,[1]Src!$B$2:$AI$130,7,0),"") -> 829 | AN21: =IFERROR(VLOOKUP($C21,[1]Src!$B$2:$AI$130,8,0),"") -> 39 | AO21: =IFERROR(VLOOKUP($C21,[1]Src!$B$2:$AI$130,9,0),"") -> 32 | AP21: =IFERROR(VLOOKUP($C21,[1]Src!$B$2:$AI$130,10,0),"") -> 245 | AQ21: =AO21/$AN21 -> 0.82051282 | AR21: =AP21/$AN21 -> 6.2820513
A22: =LEFT(D22,2) -> #VALUE! | B22: =[1]Src!S12 -> 21 | C22: =[1]Src!B12 -> 45110 | D22: =MID(C22,3,2)&"."&ROUNDUP(MID(C22,6,2)/3,0)&"Q" -> #VALUE! | E22: =IFERROR(VLOOKUP($C22,[1]Src!$B:$AI,3,0),"") -> 18135 | F22: =IFERROR(VLOOKUP($C22,[1]Src!$B:$AI,4,0),"") -> 8935 | G22: =IFERROR(VLOOKUP($C22,[1]Src!$B:$AI,5,0),"") -> 12717 | H22: =IFERROR(VLOOKUP($C22,[1]Src!$B:$AI,10,0),"") -> 167 | I22: =SUM(H19:H22) -> 527 | J22: =E22/SUM($H19:$H22) -> 34.411765 | K22: =F22/SUM($H19:$H22) -> 16.954459 | L22: =SUM(H22:H25) -> 744 | M22: =E22/SUM($H22:$H25) -> 24.375 | N22: =F22/SUM($H22:$H25) -> 12.009409 | P22: =MAX(E22:E23)/SUM($H22:$H25) -> 24.375 | Q22: =MIN(F22:F23)/SUM($H22:$H25) -> 10.580645 | R22: =SUM(H18:H21) -> 489 | S22: =MAX(E22:E25)/SUM($H18:$H21) -> 37.08589 | T22: =MIN(F22:F25)/SUM($H18:$H21) -> 9.2760736 | AC22: =D23 -> #VALUE! | AJ22: 26년 | AK22: =[1]my리포트!AG378 -> #REF! | AL22: =MID(C22,3,2)&"."&ROUNDUP(MID(C22,6,2)/3,0)&"Q" -> #VALUE! | AM22: =IFERROR(VLOOKUP($C22,[1]Src!$B$2:$AI$130,7,0),"") -> 524 | AN22: =IFERROR(VLOOKUP($C22,[1]Src!$B$2:$AI$130,8,0),"") -> 33 | AO22: =IFERROR(VLOOKUP($C22,[1]Src!$B$2:$AI$130,9,0),"") -> 22 | AP22: =IFERROR(VLOOKUP($C22,[1]Src!$B$2:$AI$130,10,0),"") -> 167 | AQ22: =AO22/$AN22 -> 0.66666667 | AR22: =AP22/$AN22 -> 5.0606061
A23: =LEFT(D23,2) -> #VALUE! | B23: =[1]Src!S13 -> 36.3 | C23: =[1]Src!B13 -> 45019 | D23: =MID(C23,3,2)&"."&ROUNDUP(MID(C23,6,2)/3,0)&"Q" -> #VALUE! | E23: =IFERROR(VLOOKUP($C23,[1]Src!$B:$AI,3,0),"") -> 14344 | F23: =IFERROR(VLOOKUP($C23,[1]Src!$B:$AI,4,0),"") -> 7872 | G23: =IFERROR(VLOOKUP($C23,[1]Src!$B:$AI,5,0),"") -> 11499 | H23: =IFERROR(VLOOKUP($C23,[1]Src!$B:$AI,10,0),"") -> 265 | I23: =SUM(H20:H23) -> 687 | J23: =E23/SUM($H20:$H23) -> 20.879185 | K23: =F23/SUM($H20:$H23) -> 11.458515 | L23: =SUM(H23:H26) -> 650 | M23: =E23/SUM($H23:$H26) -> 22.067692 | N23: =F23/SUM($H23:$H26) -> 12.110769 | O23: =SUM(H23:H26) -> 650 | P23: =MAX(E23:E24)/SUM($H23:$H26) -> 22.067692 | Q23: =MIN(F23:F24)/SUM($H23:$H26) -> 10.838462 | R23: =SUM(H19:H22) -> 527 | S23: =MAX(E23:E26)/SUM($H19:$H22) -> 27.218216 | T23: =MIN(F23:F26)/SUM($H19:$H22) -> 8.597723 | AC23: =D24 -> #VALUE! | AJ23: 27년 | AK23: =[1]my리포트!AH378 -> #REF! | AL23: =MID(C23,3,2)&"."&ROUNDUP(MID(C23,6,2)/3,0)&"Q" -> #VALUE! | AM23: =IFERROR(VLOOKUP($C23,[1]Src!$B$2:$AI$130,7,0),"") -> 502 | AN23: =IFERROR(VLOOKUP($C23,[1]Src!$B$2:$AI$130,8,0),"") -> 44 | AO23: =IFERROR(VLOOKUP($C23,[1]Src!$B$2:$AI$130,9,0),"") -> 35 | AP23: =IFERROR(VLOOKUP($C23,[1]Src!$B$2:$AI$130,10,0),"") -> 265 | AQ23: =AO23/$AN23 -> 0.79545455 | AR23: =AP23/$AN23 -> 6.0227273
A24: =LEFT(D24,2) -> #VALUE! | B24: =[1]Src!S14 -> 18.09 | C24: =[1]Src!B14 -> 44928 | D24: =MID(C24,3,2)&"."&ROUNDUP(MID(C24,6,2)/3,0)&"Q" -> #VALUE! | E24: =IFERROR(VLOOKUP($C24,[1]Src!$B:$AI,3,0),"") -> 9117 | F24: =IFERROR(VLOOKUP($C24,[1]Src!$B:$AI,4,0),"") -> 7045 | G24: =IFERROR(VLOOKUP($C24,[1]Src!$B:$AI,5,0),"") -> 8181 | H24: =IFERROR(VLOOKUP($C24,[1]Src!$B:$AI,10,0),"") -> 124 | I24: =SUM(H21:H24) -> 801 | J24: =E24/SUM($H21:$H24) -> 11.382022 | K24: =F24/SUM($H21:$H24) -> 8.7952559 | L24: =SUM(H24:H27) -> 547 | M24: =E24/SUM($H24:$H27) -> 16.667276 | N24: =F24/SUM($H24:$H27) -> 12.879342 | O24: =SUM(H24:H27) -> 547 | P24: =MAX(E24:E25)/SUM($H24:$H27) -> 20.274223 | Q24: =MIN(F24:F25)/SUM($H24:$H27) -> 8.2925046 | R24: =SUM(H20:H23) -> 687 | S24: =MAX(E24:E27)/SUM($H20:$H23) -> 16.142649 | T24: =MIN(F24:F27)/SUM($H20:$H23) -> 4.9941776 | AC24: =D29 -> #VALUE! | AL24: =MID(C24,3,2)&"."&ROUNDUP(MID(C24,6,2)/3,0)&"Q" -> #VALUE! | AM24: =IFERROR(VLOOKUP($C24,[1]Src!$B$2:$AI$130,7,0),"") -> 395 | AN24: =IFERROR(VLOOKUP($C24,[1]Src!$B$2:$AI$130,8,0),"") -> 24 | AO24: =IFERROR(VLOOKUP($C24,[1]Src!$B$2:$AI$130,9,0),"") -> 16 | AP24: =IFERROR(VLOOKUP($C24,[1]Src!$B$2:$AI$130,10,0),"") -> 124 | AQ24: =AO24/$AN24 -> 0.66666667 | AR24: =AP24/$AN24 -> 5.1666667
A25: =LEFT(D25,2) -> #VALUE! | B25: =[1]Src!S15 -> 29.14 | C25: =[1]Src!B15 -> 44838 | D25: =MID(C25,3,2)&"."&ROUNDUP(MID(C25,6,2)/3,0)&"Q" -> #VALUE! | E25: =IFERROR(VLOOKUP($C25,[1]Src!$B:$AI,3,0),"") -> 11090 | F25: =IFERROR(VLOOKUP($C25,[1]Src!$B:$AI,4,0),"") -> 4536 | G25: =IFERROR(VLOOKUP($C25,[1]Src!$B:$AI,5,0),"") -> 7736 | H25: =IFERROR(VLOOKUP($C25,[1]Src!$B:$AI,10,0),"") -> 188 | I25: =SUM(H22:H25) -> 744 | J25: =E25/SUM($H22:$H25) -> 14.905914 | K25: =F25/SUM($H22:$H25) -> 6.0967742 | L25: =SUM(H25:H28) -> 465 | M25: =E25/SUM($H25:$H28) -> 23.849462 | N25: =F25/SUM($H25:$H28) -> 9.7548387 | P25: =MAX(E25:E26)/SUM($H25:$H28) -> 23.849462 | Q25: =MIN(F25:F26)/SUM($H25:$H28) -> 9.744086 | R25: =SUM(H21:H24) -> 801 | S25: =MAX(E25:E28)/SUM($H21:$H24) -> 13.845194 | T25: =MIN(F25:F28)/SUM($H21:$H24) -> 3.7565543 | U25: =INT(LEFT(D25,2)) -> #VALUE! | AC25: =D30 -> #VALUE! | AJ25: 0.9 | AL25: =MID(C25,3,2)&"."&ROUNDUP(MID(C25,6,2)/3,0)&"Q" -> #VALUE! | AM25: =IFERROR(VLOOKUP($C25,[1]Src!$B$2:$AI$130,7,0),"") -> 771 | AN25: =IFERROR(VLOOKUP($C25,[1]Src!$B$2:$AI$130,8,0),"") -> 33 | AO25: =IFERROR(VLOOKUP($C25,[1]Src!$B$2:$AI$130,9,0),"") -> 25 | AP25: =IFERROR(VLOOKUP($C25,[1]Src!$B$2:$AI$130,10,0),"") -> 188 | AQ25: =AO25/$AN25 -> 0.75757576 | AR25: =AP25/$AN25 -> 5.6969697
A26: =LEFT(D26,2) -> #VALUE! | B26: =[1]Src!S16 -> 12.13 | C26: =[1]Src!B16 -> 44743 | D26: =MID(C26,3,2)&"."&ROUNDUP(MID(C26,6,2)/3,0)&"Q" -> #VALUE! | E26: =IFERROR(VLOOKUP($C26,[1]Src!$B:$AI,3,0),"") -> 6508 | F26: =IFERROR(VLOOKUP($C26,[1]Src!$B:$AI,4,0),"") -> 4531 | G26: =IFERROR(VLOOKUP($C26,[1]Src!$B:$AI,5,0),"") -> 4572 | H26: =IFERROR(VLOOKUP($C26,[1]Src!$B:$AI,10,0),"") -> 73 | I26: =SUM(H23:H26) -> 650 | J26: =E26/SUM($H23:$H26) -> 10.012308 | K26: =F26/SUM($H23:$H26) -> 6.9707692 | L26: =SUM(H26:H29) -> 486 | M26: =E26/SUM($H26:$H29) -> 13.390947 | N26: =F26/SUM($H26:$H29) -> 9.3230453 | P26: =MAX(E26:E27)/SUM($H26:$H29) -> 14.794239 | Q26: =MIN(F26:F27)/SUM($H26:$H29) -> 7.0596708 | R26: =SUM(W22:W25) -> 0 | S26: =MAX(E26:E29)/SUM($H22:$H25) -> 9.6639785 | T26: =MIN(F26:F29)/SUM($H22:$H25) -> 4.0443548 | AC26: =D31 -> #VALUE! | AJ26: 25년 | AK26: =AK21*$AJ$25 -> #REF! | AL26: =MID(C26,3,2)&"."&ROUNDUP(MID(C26,6,2)/3,0)&"Q" -> #VALUE! | AM26: =IFERROR(VLOOKUP($C26,[1]Src!$B$2:$AI$130,7,0),"") -> 347 | AN26: =IFERROR(VLOOKUP($C26,[1]Src!$B$2:$AI$130,8,0),"") -> 14 | AO26: =IFERROR(VLOOKUP($C26,[1]Src!$B$2:$AI$130,9,0),"") -> 10 | AP26: =IFERROR(VLOOKUP($C26,[1]Src!$B$2:$AI$130,10,0),"") -> 73 | AQ26: =AO26/$AN26 -> 0.71428571 | AR26: =AP26/$AN26 -> 5.2142857
A27: =LEFT(D27,2) -> #VALUE! | B27: =[1]Src!S17 -> 28.09 | C27: =[1]Src!B17 -> 44652 | D27: =MID(C27,3,2)&"."&ROUNDUP(MID(C27,6,2)/3,0)&"Q" -> #VALUE! | E27: =IFERROR(VLOOKUP($C27,[1]Src!$B:$AI,3,0),"") -> 7190 | F27: =IFERROR(VLOOKUP($C27,[1]Src!$B:$AI,4,0),"") -> 3431 | G27: =IFERROR(VLOOKUP($C27,[1]Src!$B:$AI,5,0),"") -> 5890 | H27: =IFERROR(VLOOKUP($C27,[1]Src!$B:$AI,10,0),"") -> 162 | I27: =SUM(H24:H27) -> 547 | J27: =E27/SUM($H24:$H27) -> 13.144424 | K27: =F27/SUM($H24:$H27) -> 6.2723949 | L27: =SUM(H27:H30) -> 481 | M27: =E27/SUM($H27:$H30) -> 14.948025 | N27: =F27/SUM($H27:$H30) -> 7.1330561 | O27: =SUM(H27:H30) -> 481 | P27: =MAX(E27:E28)/SUM($H27:$H30) -> 14.948025 | Q27: =MIN(F27:F28)/SUM($H27:$H30) -> 6.2557173 | R27: =SUM(W23:W26) -> 0 | S27: =MAX(E27:E30)/SUM($H23:$H26) -> 11.061538 | T27: =MIN(F27:F30)/SUM($H23:$H26) -> 4.6292308 | AC27: =D32 -> #VALUE! | AJ27: 26년 | AK27: =AK22*$AJ$25 -> #REF! | AL27: =MID(C27,3,2)&"."&ROUNDUP(MID(C27,6,2)/3,0)&"Q" -> #VALUE! | AM27: =IFERROR(VLOOKUP($C27,[1]Src!$B$2:$AI$130,7,0),"") -> 368 | AN27: =IFERROR(VLOOKUP($C27,[1]Src!$B$2:$AI$130,8,0),"") -> 31 | AO27: =IFERROR(VLOOKUP($C27,[1]Src!$B$2:$AI$130,9,0),"") -> 21 | AP27: =IFERROR(VLOOKUP($C27,[1]Src!$B$2:$AI$130,10,0),"") -> 162 | AQ27: =AO27/$AN27 -> 0.67741935 | AR27: =AP27/$AN27 -> 5.2258065
A28: =LEFT(D28,2) -> #VALUE! | B28: =[1]Src!S18 -> 7.56 | C28: =[1]Src!B18 -> 44564 | D28: =MID(C28,3,2)&"."&ROUNDUP(MID(C28,6,2)/3,0)&"Q" -> #VALUE! | E28: =IFERROR(VLOOKUP($C28,[1]Src!$B:$AI,3,0),"") -> 3991 | F28: =IFERROR(VLOOKUP($C28,[1]Src!$B:$AI,4,0),"") -> 3009 | G28: =IFERROR(VLOOKUP($C28,[1]Src!$B:$AI,5,0),"") -> 3591 | H28: =IFERROR(VLOOKUP($C28,[1]Src!$B:$AI,10,0),"") -> 42 | I28: =SUM(H25:H28) -> 465 | J28: =E28/SUM($H25:$H28) -> 8.5827957 | K28: =F28/SUM($H25:$H28) -> 6.4709677 | L28: =SUM(H28:H31) -> 455 | M28: =E28/SUM($H28:$H31) -> 8.7714286 | N28: =F28/SUM($H28:$H31) -> 6.6131868 | O28: =SUM(H28:H31) -> 455 | P28: =MAX(E28:E29)/SUM($H28:$H31) -> 8.7714286 | Q28: =MIN(F28:F29)/SUM($H28:$H31) -> 6.6131868 | R28: =SUM(W24:W27) -> 0 | S28: =MAX(E28:E31)/SUM($H24:$H27) -> 9.1407678 | T28: =MIN(F28:F31)/SUM($H24:$H27) -> 5.5009141 | AC28: =D33 -> #VALUE! | AJ28: 27년 | AK28: =AK23*$AJ$25 -> #REF! | AL28: =MID(C28,3,2)&"."&ROUNDUP(MID(C28,6,2)/3,0)&"Q" -> #VALUE! | AM28: =IFERROR(VLOOKUP($C28,[1]Src!$B$2:$AI$130,7,0),"") -> 219 | AN28: =IFERROR(VLOOKUP($C28,[1]Src!$B$2:$AI$130,8,0),"") -> 7 | AO28: =IFERROR(VLOOKUP($C28,[1]Src!$B$2:$AI$130,9,0),"") -> 5 | AP28: =IFERROR(VLOOKUP($C28,[1]Src!$B$2:$AI$130,10,0),"") -> 42 | AQ28: =AO28/$AN28 -> 0.71428571 | AR28: =AP28/$AN28 -> 6
A29: =LEFT(D29,2) -> #VALUE! | B29: =[1]Src!S19 -> 0 | C29: =[1]Src!B19 -> 44470 | D29: =MID(C29,3,2)&"."&ROUNDUP(MID(C29,6,2)/3,0)&"Q" -> #VALUE! | E29: =IFERROR(VLOOKUP($C29,[1]Src!$B:$AI,3,0),"") -> 3981 | F29: =IFERROR(VLOOKUP($C29,[1]Src!$B:$AI,4,0),"") -> 3331 | G29: =IFERROR(VLOOKUP($C29,[1]Src!$B:$AI,5,0),"") -> 3604 | H29: =IFERROR(VLOOKUP($C29,[1]Src!$B:$AI,10,0),"") -> 209 | I29: =SUM(H26:H29) -> 486 | J29: =E29/SUM($H26:$H29) -> 8.191358 | K29: =F29/SUM($H26:$H29) -> 6.8539095 | L29: =SUM(H29:H32) -> 478 | M29: =E29/SUM($H29:$H32) -> 8.3284519 | N29: =F29/SUM($H29:$H32) -> 6.9686192 | P29: =MAX(E29:E30)/SUM($H29:$H32) -> 10.269874 | Q29: =MIN(F29:F30)/SUM($H29:$H32) -> 6.9686192 | R29: =SUM(W25:W28) -> 0 | S29: =MAX(E29:E32)/SUM($H25:$H28) -> 11.748387 | T29: =MIN(F29:F32)/SUM($H25:$H28) -> 7.1634409 | U29: =INT(LEFT(D29,2)) -> #VALUE! | AC29: =D34 -> #VALUE! | AL29: =MID(C29,3,2)&"."&ROUNDUP(MID(C29,6,2)/3,0)&"Q" -> #VALUE! | AM29: =IFERROR(VLOOKUP($C29,[1]Src!$B$2:$AI$130,7,0),"") -> 515 | AN29: =IFERROR(VLOOKUP($C29,[1]Src!$B$2:$AI$130,8,0),"") -> 30 | AO29: =IFERROR(VLOOKUP($C29,[1]Src!$B$2:$AI$130,9,0),"") -> 27 | AP29: =IFERROR(VLOOKUP($C29,[1]Src!$B$2:$AI$130,10,0),"") -> 209 | AQ29: =AO29/$AN29 -> 0.9 | AR29: =AP29/$AN29 -> 6.9666667
A30: =LEFT(D30,2) -> #VALUE! | B30: =[1]Src!S20 -> 13.86 | C30: =[1]Src!B20 -> 44378 | D30: =MID(C30,3,2)&"."&ROUNDUP(MID(C30,6,2)/3,0)&"Q" -> #VALUE! | E30: =IFERROR(VLOOKUP($C30,[1]Src!$B:$AI,3,0),"") -> 4909 | F30: =IFERROR(VLOOKUP($C30,[1]Src!$B:$AI,4,0),"") -> 3436 | G30: =IFERROR(VLOOKUP($C30,[1]Src!$B:$AI,5,0),"") -> 3631 | H30: =IFERROR(VLOOKUP($C30,[1]Src!$B:$AI,10,0),"") -> 68 | I30: =SUM(H27:H30) -> 481 | J30: =E30/SUM($H27:$H30) -> 10.205821 | K30: =F30/SUM($H27:$H30) -> 7.1434511 | L30: =SUM(H30:H33) -> 419 | M30: =E30/SUM($H30:$H33) -> 11.71599 | N30: =F30/SUM($H30:$H33) -> 8.2004773 | P30: =MAX(E30:E31)/SUM($H30:$H33) -> 11.933174 | Q30: =MIN(F30:F31)/SUM($H30:$H33) -> 8.2004773 | R30: =SUM(H26:H29) -> 486 | S30: =MAX(E30:E33)/SUM($H26:$H29) -> 12.718107 | T30: =MIN(F30:F33)/SUM($H26:$H29) -> 5.7201646 | AC30: =D35 -> #VALUE! | AL30: =MID(C30,3,2)&"."&ROUNDUP(MID(C30,6,2)/3,0)&"Q" -> #VALUE! | AM30: =IFERROR(VLOOKUP($C30,[1]Src!$B$2:$AI$130,7,0),"") -> 257 | AN30: =IFERROR(VLOOKUP($C30,[1]Src!$B$2:$AI$130,8,0),"") -> 14 | AO30: =IFERROR(VLOOKUP($C30,[1]Src!$B$2:$AI$130,9,0),"") -> 9 | AP30: =IFERROR(VLOOKUP($C30,[1]Src!$B$2:$AI$130,10,0),"") -> 68 | AQ30: =AO30/$AN30 -> 0.64285714 | AR30: =AP30/$AN30 -> 4.8571429
A31: =LEFT(D31,2) -> #VALUE! | B31: =[1]Src!S21 -> 29.2 | C31: =[1]Src!B21 -> 44287 | D31: =MID(C31,3,2)&"."&ROUNDUP(MID(C31,6,2)/3,0)&"Q" -> #VALUE! | E31: =IFERROR(VLOOKUP($C31,[1]Src!$B:$AI,3,0),"") -> 5000 | F31: =IFERROR(VLOOKUP($C31,[1]Src!$B:$AI,4,0),"") -> 4086 | G31: =IFERROR(VLOOKUP($C31,[1]Src!$B:$AI,5,0),"") -> 4590 | H31: =IFERROR(VLOOKUP($C31,[1]Src!$B:$AI,10,0),"") -> 136 | I31: =SUM(H28:H31) -> 455 | J31: =E31/SUM($H28:$H31) -> 10.989011 | K31: =F31/SUM($H28:$H31) -> 8.9802198 | L31: =SUM(H31:H34) -> 511 | M31: =E31/SUM($H31:$H34) -> 9.7847358 | N31: =F31/SUM($H31:$H34) -> 7.9960861 | O31: =SUM(H31:H34) -> 511 | P31: =MAX(E31:E32)/SUM($H31:$H34) -> 10.690802 | Q31: =MIN(F31:F32)/SUM($H31:$H34) -> 6.7592955 | S31: =MAX(E31:E34)/SUM($H27:$H30) -> 12.850312 | T31: =MIN(F31:F34)/SUM($H27:$H30) -> 3.981289 | AC31: =D36 -> #VALUE! | AL31: =MID(C31,3,2)&"."&ROUNDUP(MID(C31,6,2)/3,0)&"Q" -> #VALUE! | AM31: =IFERROR(VLOOKUP($C31,[1]Src!$B$2:$AI$130,7,0),"") -> 234 | AN31: =IFERROR(VLOOKUP($C31,[1]Src!$B$2:$AI$130,8,0),"") -> 10 | AO31: =IFERROR(VLOOKUP($C31,[1]Src!$B$2:$AI$130,9,0),"") -> 18 | AP31: =IFERROR(VLOOKUP($C31,[1]Src!$B$2:$AI$130,10,0),"") -> 136 | AQ31: =AO31/$AN31 -> 1.8 | AR31: =AP31/$AN31 -> 13.6
A32: =LEFT(D32,2) -> #VALUE! | B32: =[1]Src!S22 -> 14.83 | C32: =[1]Src!B22 -> 44200 | D32: =MID(C32,3,2)&"."&ROUNDUP(MID(C32,6,2)/3,0)&"Q" -> #VALUE! | E32: =IFERROR(VLOOKUP($C32,[1]Src!$B:$AI,3,0),"") -> 5463 | F32: =IFERROR(VLOOKUP($C32,[1]Src!$B:$AI,4,0),"") -> 3454 | G32: =IFERROR(VLOOKUP($C32,[1]Src!$B:$AI,5,0),"") -> 4254 | H32: =IFERROR(VLOOKUP($C32,[1]Src!$B:$AI,10,0),"") -> 65 | I32: =SUM(H29:H32) -> 478 | J32: =E32/SUM($H29:$H32) -> 11.42887 | K32: =F32/SUM($H29:$H32) -> 7.2259414 | L32: =SUM(H32:H35) -> 551 | M32: =E32/SUM($H32:$H35) -> 9.9147005 | N32: =F32/SUM($H32:$H35) -> 6.2686025 | O32: =SUM(H32:H35) -> 551 | P32: =MAX(E32:E33)/SUM($H32:$H35) -> 11.217786 | Q32: =MIN(F32:F33)/SUM($H32:$H35) -> 5.0453721 | S32: =MAX(E32:E35)/SUM($H28:$H31) -> 13.584615 | T32: =MIN(F32:F35)/SUM($H28:$H31) -> 3.9582418 | AC32: =D37 -> #VALUE! | AL32: =MID(C32,3,2)&"."&ROUNDUP(MID(C32,6,2)/3,0)&"Q" -> #VALUE! | AM32: =IFERROR(VLOOKUP($C32,[1]Src!$B$2:$AI$130,7,0),"") -> 211 | AN32: =IFERROR(VLOOKUP($C32,[1]Src!$B$2:$AI$130,8,0),"") -> 4 | AO32: =IFERROR(VLOOKUP($C32,[1]Src!$B$2:$AI$130,9,0),"") -> 9 | AP32: =IFERROR(VLOOKUP($C32,[1]Src!$B$2:$AI$130,10,0),"") -> 65
A33: =LEFT(D33,2) -> #VALUE! | B33: =[1]Src!S23 -> 36.1 | C33: =[1]Src!B23 -> 44109 | D33: =MID(C33,3,2)&"."&ROUNDUP(MID(C33,6,2)/3,0)&"Q" -> #VALUE! | E33: =IFERROR(VLOOKUP($C33,[1]Src!$B:$AI,3,0),"") -> 6181 | F33: =IFERROR(VLOOKUP($C33,[1]Src!$B:$AI,4,0),"") -> 2780 | G33: =IFERROR(VLOOKUP($C33,[1]Src!$B:$AI,5,0),"") -> 5463 | H33: =IFERROR(VLOOKUP($C33,[1]Src!$B:$AI,10,0),"") -> 150 | I33: =SUM(H30:H33) -> 419 | J33: =E33/SUM($H30:$H33) -> 14.75179 | K33: =F33/SUM($H30:$H33) -> 6.6348449 | L33: =SUM(H33:H36) -> 462 | M33: =E33/SUM($H33:$H36) -> 13.378788 | N33: =F33/SUM($H33:$H36) -> 6.017316 | P33: =MAX(E33:E34)/SUM($H33:$H36) -> 13.378788 | Q33: =MIN(F33:F34)/SUM($H33:$H36) -> 4.1450216 | S33: =MAX(E33:E36)/SUM($H29:$H32) -> 12.930962 | T33: =MIN(F33:F36)/SUM($H29:$H32) -> 3.167364 | U33: =INT(LEFT(D33,2)) -> #VALUE! | AC33: =D38 -> #VALUE! | AL33: =MID(C33,3,2)&"."&ROUNDUP(MID(C33,6,2)/3,0)&"Q" -> #VALUE! | AM33: =IFERROR(VLOOKUP($C33,[1]Src!$B$2:$AI$130,7,0),"") -> 362 | AN33: =IFERROR(VLOOKUP($C33,[1]Src!$B$2:$AI$130,8,0),"") -> 21 | AO33: =IFERROR(VLOOKUP($C33,[1]Src!$B$2:$AI$130,9,0),"") -> 20 | AP33: =IFERROR(VLOOKUP($C33,[1]Src!$B$2:$AI$130,10,0),"") -> 150
A34: =LEFT(D34,2) -> #VALUE! | B34: =[1]Src!S24 -> 41.17 | C34: =[1]Src!B24 -> 44013 | D34: =MID(C34,3,2)&"."&ROUNDUP(MID(C34,6,2)/3,0)&"Q" -> #VALUE! | E34: =IFERROR(VLOOKUP($C34,[1]Src!$B:$AI,3,0),"") -> 3830 | F34: =IFERROR(VLOOKUP($C34,[1]Src!$B:$AI,4,0),"") -> 1915 | G34: =IFERROR(VLOOKUP($C34,[1]Src!$B:$AI,5,0),"") -> 3083 | H34: =IFERROR(VLOOKUP($C34,[1]Src!$B:$AI,10,0),"") -> 160 | I34: =SUM(H31:H34) -> 511 | J34: =E34/SUM($H31:$H34) -> 7.4951076 | K34: =F34/SUM($H31:$H34) -> 3.7475538 | L34: =SUM(H34:H37) -> 53 | M34: =E34/SUM($H34:$H37) -> 72.264151 | N34: =F34/SUM($H34:$H37) -> 36.132075 | P34: =MAX(E34:E35)/SUM($H34:$H37) -> 72.264151 | Q34: =MIN(F34:F35)/SUM($H34:$H37) -> 33.981132 | R34: =SUM(H30:H33) -> 419 | S34: =MAX(E34:E37)/SUM($H30:$H33) -> 9.1408115 | T34: =MIN(F34:F37)/SUM($H30:$H33) -> 3.6133652 | AC34: =D39 -> #VALUE! | AL34: =MID(C34,3,2)&"."&ROUNDUP(MID(C34,6,2)/3,0)&"Q" -> #VALUE! | AM34: =IFERROR(VLOOKUP($C34,[1]Src!$B$2:$AI$130,7,0),"") -> 282 | AN34: =IFERROR(VLOOKUP($C34,[1]Src!$B$2:$AI$130,8,0),"") -> 22 | AO34: =IFERROR(VLOOKUP($C34,[1]Src!$B$2:$AI$130,9,0),"") -> 21 | AP34: =IFERROR(VLOOKUP($C34,[1]Src!$B$2:$AI$130,10,0),"") -> 160
